Workbook
Name Statuses: List_Values!$A$2:$A$13

Sheet Priorities table
A1: Priority order | B1: Pack | C1: Pack name | D1: L3 Due date | E1: Hub | F1: Expected File count* | G1: JSON Requested File Count | H1: Completed file count | I1: Status | J1: Remaining works | K1: Commentary | L1: Delivery Manager | M1: L3 Date - 1 week (7 days) | P1: * This data is taken from MPDT Detailed Design tracker PowerBi. This may not be relevent as this would contain the list of all files ever assinged to the IDR, some of which may have been completed pre 2024?
A2: 1 | B2: 238.02 | C2: Ladbroke Cutting Phase 3 - Remainder​ | D2: 45623 | E2: G2S | F2: =COUNTIF(Table58[Package],IF(LEFT(Table3[[#This Row],[Pack]],1)="U",Table3[[#This Row],[Pack]],"IDR "&TRIM(Table3[[#This Row],[Pack]]))) -> 13 | G2: 13 | H2: =COUNTIFS(Table58[Package],IF(LEFT(Table3[[#This Row],[Pack]],1)="U",Table3[[#This Row],[Pack]],"IDR "&TRIM(Table3[[#This Row],[Pack]])),Table58[Status],"10 - Complete") -> 13 | I2: Complete | J2: =SUM(Table3[[#This Row],[JSON Requested File Count]]-Table3[[#This Row],[Completed file count]]) -> 0 | M2: =Table3[[#This Row],[L3 Due date]]-7 -> 45616
A3: 2 | B3: UFDR 229.D | C3: Banbury Road Main Works | D3: 45630 | E3: G2S | F3: =COUNTIF(Table58[Package],IF(LEFT(Table3[[#This Row],[Pack]],1)="U",Table3[[#This Row],[Pack]],"IDR "&TRIM(Table3[[#This Row],[Pack]]))) -> 7 | G3: 7 | H3: =COUNTIFS(Table58[Package],IF(LEFT(Table3[[#This Row],[Pack]],1)="U",Table3[[#This Row],[Pack]],"IDR "&TRIM(Table3[[#This Row],[Pack]])),Table58[Status],"10 - Complete") -> 7 | I3: Complete | J3: =SUM(Table3[[#This Row],[JSON Requested File Count]]-Table3[[#This Row],[Completed file count]]) -> 0 | M3: =Table3[[#This Row],[L3 Due date]]-7 -> 45623
A4: 3 | B4: 212.5 | C4: Fencing, Landscaping and MAS (Southern L1 Packages) | D4: 45635 | E4: NC2A | F4: =COUNTIF(Table58[Package],IF(LEFT(Table3[[#This Row],[Pack]],1)="U",Table3[[#This Row],[Pack]],"IDR "&TRIM(Table3[[#This Row],[Pack]]))) -> 85 | G4: 85 | H4: =COUNTIFS(Table58[Package],IF(LEFT(Table3[[#This Row],[Pack]],1)="U",Table3[[#This Row],[Pack]],"IDR "&TRIM(Table3[[#This Row],[Pack]])),Table58[Status],"10 - Complete") -> 85 | I4: Complete | J4: =SUM(Table3[[#This Row],[JSON Requested File Count]]-Table3[[#This Row],[Completed file count]]) -> 0 | M4: =Table3[[#This Row],[L3 Due date]]-7 -> 45628
A5: 4 | B5: 202.1-3 | C5: Small Dean Viaduct Network Rail Cutting Reinstatement | D5: 45665 | E5: NC2A | F5: =COUNTIF(Table58[Package],IF(LEFT(Table3[[#This Row],[Pack]],1)="U",Table3[[#This Row],[Pack]],"IDR "&TRIM(Table3[[#This Row],[Pack]]))) -> 4 | G5: 4 | H5: =COUNTIFS(Table58[Package],IF(LEFT(Table3[[#This Row],[Pack]],1)="U",Table3[[#This Row],[Pack]],"IDR "&TRIM(Table3[[#This Row],[Pack]])),Table58[Status],"10 - Complete") -> 4 | I5: Complete | J5: =SUM(Table3[[#This Row],[JSON Requested File Count]]-Table3[[#This Row],[Completed file count]]) -> 0 | M5: 45658
A6: 5 | B6: 201.0-1 | C6: South Heath Cutting and C2.T.3 | D6: 45637 | E6: NC2A | F6: =COUNTIF(Table58[Package],IF(LEFT(Table3[[#This Row],[Pack]],1)="U",Table3[[#This Row],[Pack]],"IDR "&TRIM(Table3[[#This Row],[Pack]]))) -> 22 | G6: 22 | H6: =COUNTIFS(Table58[Package],IF(LEFT(Table3[[#This Row],[Pack]],1)="U",Table3[[#This Row],[Pack]],"IDR "&TRIM(Table3[[#This Row],[Pack]])),Table58[Status],"10 - Complete") -> 22 | I6: Complete | J6: =SUM(Table3[[#This Row],[JSON Requested File Count]]-Table3[[#This Row],[Completed file count]]) -> 0 | M6: =Table3[[#This Row],[L3 Due date]]-7 -> 45630
A7: 6 | B7: UFDR 209.A | C7: Thame Valley Oxford Road (Thames Water Main 6209/6210) | D7: 45637 | E7: NC2A | F7: =COUNTIF(Table58[Package],IF(LEFT(Table3[[#This Row],[Pack]],1)="U",Table3[[#This Row],[Pack]],"IDR "&TRIM(Table3[[#This Row],[Pack]]))) -> 3 | G7: 3 | H7: =COUNTIFS(Table58[Package],IF(LEFT(Table3[[#This Row],[Pack]],1)="U",Table3[[#This Row],[Pack]],"IDR "&TRIM(Table3[[#This Row],[Pack]])),Table58[Status],"10 - Complete") -> 3 | I7: Complete | J7: =SUM(Table3[[#This Row],[JSON Requested File Count]]-Table3[[#This Row],[Completed file count]]) -> 0 | M7: =Table3[[#This Row],[L3 Due date]]-7 -> 45630
A8: 7 | B8: 215.03 | C8: Calvert Cutting Noise Barrier + Planting, Fencing and Ancillary Civils | D8: 45637 | E8: CA | F8: =COUNTIF(Table58[Package],IF(LEFT(Table3[[#This Row],[Pack]],1)="U",Table3[[#This Row],[Pack]],"IDR "&TRIM(Table3[[#This Row],[Pack]]))) -> 44 | G8: 44 | H8: =COUNTIFS(Table58[Package],IF(LEFT(Table3[[#This Row],[Pack]],1)="U",Table3[[#This Row],[Pack]],"IDR "&TRIM(Table3[[#This Row],[Pack]])),Table58[Status],"10 - Complete") -> 44 | I8: Complete | J8: =SUM(Table3[[#This Row],[JSON Requested File Count]]-Table3[[#This Row],[Completed file count]]) -> 0 | M8: =Table3[[#This Row],[L3 Due date]]-7 -> 45630
A9: 8 | B9: 224.7 | C9: Turweston Cutting Additional Landscape and Earthworks (New bunds) | D9: 45637 | E9: T2G | F9: =COUNTIF(Table58[Package],IF(LEFT(Table3[[#This Row],[Pack]],1)="U",Table3[[#This Row],[Pack]],"IDR "&TRIM(Table3[[#This Row],[Pack]]))) -> 10 | G9: 9 | H9: =COUNTIFS(Table58[Package],IF(LEFT(Table3[[#This Row],[Pack]],1)="U",Table3[[#This Row],[Pack]],"IDR "&TRIM(Table3[[#This Row],[Pack]])),Table58[Status],"10 - Complete") -> 9 | I9: Incomplete | J9: =SUM(Table3[[#This Row],[JSON Requested File Count]]-Table3[[#This Row],[Completed file count]]) -> 0 | K9: Possible file missing? Expecting JSON request | M9: =Table3[[#This Row],[L3 Due date]]-7 -> 45630
A10: 9 | B10: UFDR 223.A | C10: Featherbed Lane - Permanent Diversions | D10: 45637 | E10: T2G | F10: =COUNTIF(Table58[Package],IF(LEFT(Table3[[#This Row],[Pack]],1)="U",Table3[[#This Row],[Pack]],"IDR "&TRIM(Table3[[#This Row],[Pack]]))) -> 1 | G10: 1 | H10: =COUNTIFS(Table58[Package],IF(LEFT(Table3[[#This Row],[Pack]],1)="U",Table3[[#This Row],[Pack]],"IDR "&TRIM(Table3[[#This Row],[Pack]])),Table58[Status],"10 - Complete") -> 1 | I10: Complete | J10: =SUM(Table3[[#This Row],[JSON Requested File Count]]-Table3[[#This Row],[Completed file count]]) -> 0 | M10: =Table3[[#This Row],[L3 Due date]]-7 -> 45630
A11: 10 | B11: 233.01-3 | C11: Chipping Warden Green Tunnel - Associated Assets South - Part 3 | D11: 45637 | E11: G2S | F11: =COUNTIF(Table58[Package],IF(LEFT(Table3[[#This Row],[Pack]],1)="U",Table3[[#This Row],[Pack]],"IDR "&TRIM(Table3[[#This Row],[Pack]]))) -> 32 | G11: 32 | H11: =COUNTIFS(Table58[Package],IF(LEFT(Table3[[#This Row],[Pack]],1)="U",Table3[[#This Row],[Pack]],"IDR "&TRIM(Table3[[#This Row],[Pack]])),Table58[Status],"10 - Complete") -> 32 | I11: Complete | J11: =SUM(Table3[[#This Row],[JSON Requested File Count]]-Table3[[#This Row],[Completed file count]]) -> 0 | M11: =Table3[[#This Row],[L3 Due date]]-7 -> 45630
A12: 11 | B12: 214.06 | C12: Sheephouse Wood Bat Mitigation Structure - Full - Mesh panels | D12: 45638 | E12: CA | F12: =COUNTIF(Table58[Package],IF(LEFT(Table3[[#This Row],[Pack]],1)="U",Table3[[#This Row],[Pack]],"IDR "&TRIM(Table3[[#This Row],[Pack]]))) -> 7 | G12: 2 | H12: =COUNTIFS(Table58[Package],IF(LEFT(Table3[[#This Row],[Pack]],1)="U",Table3[[#This Row],[Pack]],"IDR "&TRIM(Table3[[#This Row],[Pack]])),Table58[Status],"10 - Complete") -> 2 | I12: Incomplete | J12: =SUM(Table3[[#This Row],[JSON Requested File Count]]-Table3[[#This Row],[Completed file count]]) -> 0 | K12: MPDT suggests that we are expecting 5 further JSON requests? 02-Jan-2025 - Is this correct? Have these been withdrawn? Expecting JSON request | M12: =Table3[[#This Row],[L3 Due date]]-7 -> 45631
A13: 12 | B13: UFDR 211.A | C13: Waddesdon (UKPN) | D13: 45642 | E13: NC2A | F13: =COUNTIF(Table58[Package],IF(LEFT(Table3[[#This Row],[Pack]],1)="U",Table3[[#This Row],[Pack]],"IDR "&TRIM(Table3[[#This Row],[Pack]]))) -> 6 | G13: 6 | H13: =COUNTIFS(Table58[Package],IF(LEFT(Table3[[#This Row],[Pack]],1)="U",Table3[[#This Row],[Pack]],"IDR "&TRIM(Table3[[#This Row],[Pack]])),Table58[Status],"10 - Complete") -> 6 | I13: Complete | J13: =SUM(Table3[[#This Row],[JSON Requested File Count]]-Table3[[#This Row],[Completed file count]]) -> 0 | M13: =Table3[[#This Row],[L3 Due date]]-7 -> 45635
A14: 13 | B14: 213.07-1 | C14: Quainton Cutting Ancillary Civils Fencing and Planting | D14: 45644 | E14: CA | F14: =COUNTIF(Table58[Package],IF(LEFT(Table3[[#This Row],[Pack]],1)="U",Table3[[#This Row],[Pack]],"IDR "&TRIM(Table3[[#This Row],[Pack]]))) -> 34 | G14: 33 | H14: =COUNTIFS(Table58[Package],IF(LEFT(Table3[[#This Row],[Pack]],1)="U",Table3[[#This Row],[Pack]],"IDR "&TRIM(Table3[[#This Row],[Pack]])),Table58[Status],"10 - Complete") -> 33 | I14: Complete | J14: =SUM(Table3[[#This Row],[JSON Requested File Count]]-Table3[[#This Row],[Completed file count]]) -> 0 | K14: Possible file missing? Expecting JSON request | M14: =Table3[[#This Row],[L3 Due date]]-7 -> 45637
A15: 14 | B15: UFDR 214.A | C15: FCC Sidings | D15: 45644 | E15: CA | F15: =COUNTIF(Table58[Package],IF(LEFT(Table3[[#This Row],[Pack]],1)="U",Table3[[#This Row],[Pack]],"IDR "&TRIM(Table3[[#This Row],[Pack]]))) -> 7 | G15: 7 | H15: =COUNTIFS(Table58[Package],IF(LEFT(Table3[[#This Row],[Pack]],1)="U",Table3[[#This Row],[Pack]],"IDR "&TRIM(Table3[[#This Row],[Pack]])),Table58[Status],"10 - Complete") -> 7 | I15: Complete | J15: =SUM(Table3[[#This Row],[JSON Requested File Count]]-Table3[[#This Row],[Completed file count]]) -> 0 | M15: =Table3[[#This Row],[L3 Due date]]-7 -> 45637
A16: 15 | B16: UFDR 216.I | C16: West St IP Gas Permanent diversion | D16: 45644 | E16: CA | F16: =COUNTIF(Table58[Package],IF(LEFT(Table3[[#This Row],[Pack]],1)="U",Table3[[#This Row],[Pack]],"IDR "&TRIM(Table3[[#This Row],[Pack]]))) -> 2 | G16: 2 | H16: =COUNTIFS(Table58[Package],IF(LEFT(Table3[[#This Row],[Pack]],1)="U",Table3[[#This Row],[Pack]],"IDR "&TRIM(Table3[[#This Row],[Pack]])),Table58[Status],"10 - Complete") -> 2 | I16: Complete | J16: =SUM(Table3[[#This Row],[JSON Requested File Count]]-Table3[[#This Row],[Completed file count]]) -> 0 | M16: =Table3[[#This Row],[L3 Due date]]-7 -> 45637
A17: 16 | B17: 202.5-2 | C17: Small Dean North Embankment ( Remainder) | D17: 45665 | E17: NC2A | F17: =COUNTIF(Table58[Package],IF(LEFT(Table3[[#This Row],[Pack]],1)="U",Table3[[#This Row],[Pack]],"IDR "&TRIM(Table3[[#This Row],[Pack]]))) -> 1 | G17: 1 | H17: =COUNTIFS(Table58[Package],IF(LEFT(Table3[[#This Row],[Pack]],1)="U",Table3[[#This Row],[Pack]],"IDR "&TRIM(Table3[[#This Row],[Pack]])),Table58[Status],"10 - Complete") -> 1 | I17: Complete | J17: =SUM(Table3[[#This Row],[JSON Requested File Count]]-Table3[[#This Row],[Completed file count]]) -> 0 | M17: =Table3[[#This Row],[L3 Due date]]-7 -> 45658
A18: 17 | B18: 229.01-2 | C18: Greatworth Green Tunnel Portal North | D18: 45679 | E18: G2S | F18: =COUNTIF(Table58[Package],IF(LEFT(Table3[[#This Row],[Pack]],1)="U",Table3[[#This Row],[Pack]],"IDR "&TRIM(Table3[[#This Row],[Pack]]))) -> 30 | G18: 28 | H18: =COUNTIFS(Table58[Package],IF(LEFT(Table3[[#This Row],[Pack]],1)="U",Table3[[#This Row],[Pack]],"IDR "&TRIM(Table3[[#This Row],[Pack]])),Table58[Status],"10 - Complete") -> 28 | I18: Incomplete | J18: =SUM(Table3[[#This Row],[JSON Requested File Count]]-Table3[[#This Row],[Completed file count]]) -> 0 | K18: Expecting JSON requests. | M18: =Table3[[#This Row],[L3 Due date]]-7 -> 45672
A19: 19 | B19: 202.5-2_2 | C19: Small Dean North Embankment - Grove Farm Accommodation Underbridge and track drainage | D19: Mar | E19: NC2A | F19: =COUNTIF(Table58[Package],IF(LEFT(Table3[[#This Row],[Pack]],1)="U",Table3[[#This Row],[Pack]],"IDR "&TRIM(Table3[[#This Row],[Pack]]))) -> 1 | G19: 1 | H19: =COUNTIFS(Table58[Package],IF(LEFT(Table3[[#This Row],[Pack]],1)="U",Table3[[#This Row],[Pack]],"IDR "&TRIM(Table3[[#This Row],[Pack]])),Table58[Status],"10 - Complete") -> 1 | I19: Complete | J19: =SUM(Table3[[#This Row],[JSON Requested File Count]]-Table3[[#This Row],[Completed file count]]) -> 0 | M19: 45658
A20: 20 | B20: 219.1 | C20: Noise Barriers | D20: Mar | E20: T2G | F20: =COUNTIF(Table58[Package],IF(LEFT(Table3[[#This Row],[Pack]],1)="U",Table3[[#This Row],[Pack]],"IDR "&TRIM(Table3[[#This Row],[Pack]]))) -> 10 | G20: 1 | H20: =COUNTIFS(Table58[Package],IF(LEFT(Table3[[#This Row],[Pack]],1)="U",Table3[[#This Row],[Pack]],"IDR "&TRIM(Table3[[#This Row],[Pack]])),Table58[Status],"10 - Complete") -> 1 | I20: Complete | J20: =SUM(Table3[[#This Row],[JSON Requested File Count]]-Table3[[#This Row],[Completed file count]]) -> 0 | K20: Expecting JSON requests. | M20: 45665
A21: 18 | B21: 222.9 | C21: Barton to Mixbury Cutting - Ancillary Civils Fencing and Landscape Planting | D21: 45679 | E21: T2G | F21: =COUNTIF(Table58[Package],IF(LEFT(Table3[[#This Row],[Pack]],1)="U",Table3[[#This Row],[Pack]],"IDR "&TRIM(Table3[[#This Row],[Pack]]))) -> 102 | G21: 74 | H21: =COUNTIFS(Table58[Package],IF(LEFT(Table3[[#This Row],[Pack]],1)="U",Table3[[#This Row],[Pack]],"IDR "&TRIM(Table3[[#This Row],[Pack]])),Table58[Status],"10 - Complete") -> 74 | I21: Incomplete | J21: =SUM(Table3[[#This Row],[JSON Requested File Count]]-Table3[[#This Row],[Completed file count]]) -> 0 | K21: Expecting JSON requests. | M21: 45672
A22: 21 | B22: 214.07 | C22: Grendon and Woodlands, Fencing, Ancillary Civils and Planting, Fencing package 4 | D22: Feb | F22: =COUNTIF(Table58[Package],IF(LEFT(Table3[[#This Row],[Pack]],1)="U",Table3[[#This Row],[Pack]],"IDR "&TRIM(Table3[[#This Row],[Pack]]))) -> 43 | G22: 21 | H22: =COUNTIFS(Table58[Package],IF(LEFT(Table3[[#This Row],[Pack]],1)="U",Table3[[#This Row],[Pack]],"IDR "&TRIM(Table3[[#This Row],[Pack]])),Table58[Status],"10 - Complete") -> 20 | I22: Incomplete | J22: =SUM(Table3[[#This Row],[JSON Requested File Count]]-Table3[[#This Row],[Completed file count]]) -> 1 | K22: Expecting JSON requests. | M22: Date not clear
A23: 22 | B23: UFDR 202.B | C23: ​Rocky Lane (UKPN 1203, Thames Water Main 6200, BT Openreach 3101)​ | D23: Feb | F23: =COUNTIF(Table58[Package],IF(LEFT(Table3[[#This Row],[Pack]],1)="U",Table3[[#This Row],[Pack]],"IDR "&TRIM(Table3[[#This Row],[Pack]]))) -> 5 | G23: 5 | H23: =COUNTIFS(Table58[Package],IF(LEFT(Table3[[#This Row],[Pack]],1)="U",Table3[[#This Row],[Pack]],"IDR "&TRIM(Table3[[#This Row],[Pack]])),Table58[Status],"10 - Complete") -> 5 | I23: Incomplete | J23: =SUM(Table3[[#This Row],[JSON Requested File Count]]-Table3[[#This Row],[Completed file count]]) -> 0 | K23: all at PCRA. | M23: Date not clear
A24: 23 | B24: 204.1-1 | C24: Wendover North Cutting re-submission (to include Wendover North Cutting Portal Access Road​ | D24: Mar | F24: =COUNTIF(Table58[Package],IF(LEFT(Table3[[#This Row],[Pack]],1)="U",Table3[[#This Row],[Pack]],"IDR "&TRIM(Table3[[#This Row],[Pack]]))) -> 9 | G24: 6 | H24: =COUNTIFS(Table58[Package],IF(LEFT(Table3[[#This Row],[Pack]],1)="U",Table3[[#This Row],[Pack]],"IDR "&TRIM(Table3[[#This Row],[Pack]])),Table58[Status],"10 - Complete") -> 6 | I24: Incomplete | J24: =SUM(Table3[[#This Row],[JSON Requested File Count]]-Table3[[#This Row],[Completed file count]]) -> 0 | K24: legacy files in tracker complete. Expecting JSON requests. | M24: Date not clear
A25: 24 | B25: 214.08 | C25: Greatmoor (FCC) Sidings (structure & drainage) ​ | D25: Mar | F25: =COUNTIF(Table58[Package],IF(LEFT(Table3[[#This Row],[Pack]],1)="U",Table3[[#This Row],[Pack]],"IDR "&TRIM(Table3[[#This Row],[Pack]]))) -> 8 | G25: 1 | H25: =COUNTIFS(Table58[Package],IF(LEFT(Table3[[#This Row],[Pack]],1)="U",Table3[[#This Row],[Pack]],"IDR "&TRIM(Table3[[#This Row],[Pack]])),Table58[Status],"10 - Complete") -> 1 | I25: Incomplete | J25: =SUM(Table3[[#This Row],[JSON Requested File Count]]-Table3[[#This Row],[Completed file count]]) -> 0 | K25: Expecting JSON requests. | M25: Date not clear

Sheet Analysis
A1: Run rate | B1: Total | C1: Lee | D1: Supriyan | E1: Rakesh
A2: 45383 | B2: =COUNTIFS(Central_Team!I:I,"<"&Analysis!A2+7,Central_Team!I:I,">="&Analysis!A2) -> 35 | C2: =COUNTIFS(Central_Team!$I:$I,"<"&Analysis!$A2+7,Central_Team!$I:$I,">="&Analysis!$A2,Central_Team!$V:$V,Analysis!C$1) -> 16 | D2: =COUNTIFS(Central_Team!$I:$I,"<"&Analysis!$A2+7,Central_Team!$I:$I,">="&Analysis!$A2,Central_Team!$V:$V,Analysis!D$1) -> 19 | E2: =COUNTIFS(Central_Team!$I:$I,"<"&Analysis!$A2+7,Central_Team!$I:$I,">="&Analysis!$A2,Central_Team!$V:$V,Analysis!E$1) -> 0
A3: 45390 | B3: =COUNTIFS(Central_Team!I:I,"<"&Analysis!A3+7,Central_Team!I:I,">="&Analysis!A3) -> 26 | C3: =COUNTIFS(Central_Team!$I:$I,"<"&Analysis!$A3+7,Central_Team!$I:$I,">="&Analysis!$A3,Central_Team!$V:$V,Analysis!C$1) -> 19 | D3: =COUNTIFS(Central_Team!$I:$I,"<"&Analysis!$A3+7,Central_Team!$I:$I,">="&Analysis!$A3,Central_Team!$V:$V,Analysis!D$1) -> 7 | E3: =COUNTIFS(Central_Team!$I:$I,"<"&Analysis!$A3+7,Central_Team!$I:$I,">="&Analysis!$A3,Central_Team!$V:$V,Analysis!E$1) -> 0
A4: 45397 | B4: =COUNTIFS(Central_Team!I:I,"<"&Analysis!A4+7,Central_Team!I:I,">="&Analysis!A4) -> 27 | C4: =COUNTIFS(Central_Team!$I:$I,"<"&Analysis!$A4+7,Central_Team!$I:$I,">="&Analysis!$A4,Central_Team!$V:$V,Analysis!C$1) -> 12 | D4: =COUNTIFS(Central_Team!$I:$I,"<"&Analysis!$A4+7,Central_Team!$I:$I,">="&Analysis!$A4,Central_Team!$V:$V,Analysis!D$1) -> 14 | E4: =COUNTIFS(Central_Team!$I:$I,"<"&Analysis!$A4+7,Central_Team!$I:$I,">="&Analysis!$A4,Central_Team!$V:$V,Analysis!E$1) -> 0
A5: 45404 | B5: =COUNTIFS(Central_Team!I:I,"<"&Analysis!A5+7,Central_Team!I:I,">="&Analysis!A5) -> 58 | C5: =COUNTIFS(Central_Team!$I:$I,"<"&Analysis!$A5+7,Central_Team!$I:$I,">="&Analysis!$A5,Central_Team!$V:$V,Analysis!C$1) -> 38 | D5: =COUNTIFS(Central_Team!$I:$I,"<"&Analysis!$A5+7,Central_Team!$I:$I,">="&Analysis!$A5,Central_Team!$V:$V,Analysis!D$1) -> 20 | E5: =COUNTIFS(Central_Team!$I:$I,"<"&Analysis!$A5+7,Central_Team!$I:$I,">="&Analysis!$A5,Central_Team!$V:$V,Analysis!E$1) -> 0
A6: 45411 | B6: =COUNTIFS(Central_Team!I:I,"<"&Analysis!A6+7,Central_Team!I:I,">="&Analysis!A6) -> 57 | C6: =COUNTIFS(Central_Team!$I:$I,"<"&Analysis!$A6+7,Central_Team!$I:$I,">="&Analysis!$A6,Central_Team!$V:$V,Analysis!C$1) -> 22 | D6: =COUNTIFS(Central_Team!$I:$I,"<"&Analysis!$A6+7,Central_Team!$I:$I,">="&Analysis!$A6,Central_Team!$V:$V,Analysis!D$1) -> 35 | E6: =COUNTIFS(Central_Team!$I:$I,"<"&Analysis!$A6+7,Central_Team!$I:$I,">="&Analysis!$A6,Central_Team!$V:$V,Analysis!E$1) -> 0
A7: 45418 | B7: =COUNTIFS(Central_Team!I:I,"<"&Analysis!A7+7,Central_Team!I:I,">="&Analysis!A7) -> 37 | C7: =COUNTIFS(Central_Team!$I:$I,"<"&Analysis!$A7+7,Central_Team!$I:$I,">="&Analysis!$A7,Central_Team!$V:$V,Analysis!C$1) -> 4 | D7: =COUNTIFS(Central_Team!$I:$I,"<"&Analysis!$A7+7,Central_Team!$I:$I,">="&Analysis!$A7,Central_Team!$V:$V,Analysis!D$1) -> 16 | E7: =COUNTIFS(Central_Team!$I:$I,"<"&Analysis!$A7+7,Central_Team!$I:$I,">="&Analysis!$A7,Central_Team!$V:$V,Analysis!E$1) -> 12
A8: 45425 | B8: =COUNTIFS(Central_Team!I:I,"<"&Analysis!A8+7,Central_Team!I:I,">="&Analysis!A8) -> 21 | C8: =COUNTIFS(Central_Team!$I:$I,"<"&Analysis!$A8+7,Central_Team!$I:$I,">="&Analysis!$A8,Central_Team!$V:$V,Analysis!C$1) -> 6 | D8: =COUNTIFS(Central_Team!$I:$I,"<"&Analysis!$A8+7,Central_Team!$I:$I,">="&Analysis!$A8,Central_Team!$V:$V,Analysis!D$1) -> 9 | E8: =COUNTIFS(Central_Team!$I:$I,"<"&Analysis!$A8+7,Central_Team!$I:$I,">="&Analysis!$A8,Central_Team!$V:$V,Analysis!E$1) -> 6
A9: 45432 | B9: =COUNTIFS(Central_Team!I:I,"<"&Analysis!A9+7,Central_Team!I:I,">="&Analysis!A9) -> 27 | C9: =COUNTIFS(Central_Team!$I:$I,"<"&Analysis!$A9+7,Central_Team!$I:$I,">="&Analysis!$A9,Central_Team!$V:$V,Analysis!C$1) -> 17 | D9: =COUNTIFS(Central_Team!$I:$I,"<"&Analysis!$A9+7,Central_Team!$I:$I,">="&Analysis!$A9,Central_Team!$V:$V,Analysis!D$1) -> 2 | E9: =COUNTIFS(Central_Team!$I:$I,"<"&Analysis!$A9+7,Central_Team!$I:$I,">="&Analysis!$A9,Central_Team!$V:$V,Analysis!E$1) -> 8
A10: 45439 | B10: =COUNTIFS(Central_Team!I:I,"<"&Analysis!A10+7,Central_Team!I:I,">="&Analysis!A10) -> 51 | C10: =COUNTIFS(Central_Team!$I:$I,"<"&Analysis!$A10+7,Central_Team!$I:$I,">="&Analysis!$A10,Central_Team!$V:$V,Analysis!C$1) -> 2 | D10: =COUNTIFS(Central_Team!$I:$I,"<"&Analysis!$A10+7,Central_Team!$I:$I,">="&Analysis!$A10,Central_Team!$V:$V,Analysis!D$1) -> 20 | E10: =COUNTIFS(Central_Team!$I:$I,"<"&Analysis!$A10+7,Central_Team!$I:$I,">="&Analysis!$A10,Central_Team!$V:$V,Analysis!E$1) -> 27
A11: 45446 | B11: =COUNTIFS(Central_Team!I:I,"<"&Analysis!A11+7,Central_Team!I:I,">="&Analysis!A11) -> 66 | C11: =COUNTIFS(Central_Team!$I:$I,"<"&Analysis!$A11+7,Central_Team!$I:$I,">="&Analysis!$A11,Central_Team!$V:$V,Analysis!C$1) -> 15 | D11: =COUNTIFS(Central_Team!$I:$I,"<"&Analysis!$A11+7,Central_Team!$I:$I,">="&Analysis!$A11,Central_Team!$V:$V,Analysis!D$1) -> 22 | E11: =COUNTIFS(Central_Team!$I:$I,"<"&Analysis!$A11+7,Central_Team!$I:$I,">="&Analysis!$A11,Central_Team!$V:$V,Analysis!E$1) -> 29
A12: 45453 | B12: =COUNTIFS(Central_Team!I:I,"<"&Analysis!A12+7,Central_Team!I:I,">="&Analysis!A12) -> 51 | C12: =COUNTIFS(Central_Team!$I:$I,"<"&Analysis!$A12+7,Central_Team!$I:$I,">="&Analysis!$A12,Central_Team!$V:$V,Analysis!C$1) -> 16 | D12: =COUNTIFS(Central_Team!$I:$I,"<"&Analysis!$A12+7,Central_Team!$I:$I,">="&Analysis!$A12,Central_Team!$V:$V,Analysis!D$1) -> 12 | E12: =COUNTIFS(Central_Team!$I:$I,"<"&Analysis!$A12+7,Central_Team!$I:$I,">="&Analysis!$A12,Central_Team!$V:$V,Analysis!E$1) -> 23
A13: 45460 | B13: =COUNTIFS(Central_Team!I:I,"<"&Analysis!A13+7,Central_Team!I:I,">="&Analysis!A13) -> 22 | C13: =COUNTIFS(Central_Team!$I:$I,"<"&Analysis!$A13+7,Central_Team!$I:$I,">="&Analysis!$A13,Central_Team!$V:$V,Analysis!C$1) -> 19 | D13: =COUNTIFS(Central_Team!$I:$I,"<"&Analysis!$A13+7,Central_Team!$I:$I,">="&Analysis!$A13,Central_Team!$V:$V,Analysis!D$1) -> 0 | E13: =COUNTIFS(Central_Team!$I:$I,"<"&Analysis!$A13+7,Central_Team!$I:$I,">="&Analysis!$A13,Central_Team!$V:$V,Analysis!E$1) -> 3
... A38: 45635 | B38: =COUNTIFS(Central_Team!I:I,"<"&Analysis!A38+7,Central_Team!I:I,">="&Analysis!A38) -> 35 | C38: =COUNTIFS(Central_Team!$I:$I,"<"&Analysis!$A38+7,Central_Team!$I:$I,">="&Analysis!$A38,Central_Team!$V:$V,Analysis!C$1) -> 25 | D38: =COUNTIFS(Central_Team!$I:$I,"<"&Analysis!$A38+7,Central_Team!$I:$I,">="&Analysis!$A38,Central_Team!$V:$V,Analysis!D$1) -> 10 | E38: =COUNTIFS(Central_Team!$I:$I,"<"&Analysis!$A38+7,Central_Team!$I:$I,">="&Analysis!$A38,Central_Team!$V:$V,Analysis!E$1) -> 0
A39: Total | B39: =PERCENTILE(Table4[Total],0.85) -> 55 | C39: =PERCENTILE(C24:C38,0.85) -> 24.7 | D39: =PERCENTILE(D24:D38,0.85) -> 11 | E39: =PERCENTILE(Table4[Rakesh],0.85) -> 15

Sheet Central_Team
A1: PRIORITY R.A.G. | B1: IDR / UFDR | C1: UAID_2 | D1: L2 Asset Name | E1: ACBOS/MPDT Link | F1: Revision Submitted for JSON Works | G1: Request sent on (Date) | H1: Compliant source file received on (Date) | I1: Completion date. | J1: Immediate process requested. | K1: JSON Path | L1: Coordinate Check CE | M1: Comments Issued 1 (include Date) | N1: Response Date1 | O1: Comments 2 (include Date) | P1: Response Date2 | Q1: Comment 3 (include Date) | R1: Response Date3 | S1: Comment 4 (include Date) | T1: Response Date4 | U1: Status | V1: Action by | W1: Requester Name / Email | X1: *KPI - Measure1* | Y1: *KPI - Measure2* | Z1: *KPI - Measure3*
A2: =_xlfn.IFNA(INDEX(Table3[],MATCH(MainTracker[[#This Row],[IDR / UFDR]],Table3[Pack],0),1),"") | B2: 233.01-2 | C2: HS2-00002NJ06 | D2: Chipping Warden Green Tunnel North Portal | E2: 1MC07-CEK-TN-FRM-CS07_CL14-000001 | F2: P02 | G2: 45230 | H2: 45237 | I2: 45238 | K2: 1MC07-CEK-IM-DAT-CS07_CL14-600042 | M2: update rcvd 3/11/23 - CM_ISCI set to YES | O2: edited in house liaising with DT to get them to update MPDT on PW. | Q2: DT can update PW file post JSON creation | U2: 10 - Complete | V2: Lee | W2: Matthew Smith <MWSH@cowi.com> | X2: =IF(AND(MainTracker[[#This Row],[Completion date.]]>=45139,MainTracker[[#This Row],[Status]]="10 - Complete"),NETWORKDAYS(MAX(MainTracker[[#This Row],[Request sent on (Date)]:[Compliant source file received on (Date)]]),MainTracker[[#This Row],[Completion date.]],Holiday[Holidays])-1,"") -> 1 | Y2: =IF(AND(MainTracker[[#This Row],[Completion date.]]>=45139,MainTracker[[#This Row],[Status]]="10 - Complete"),COUNTA(MainTracker[[#This Row],[Comments Issued 1 (include Date)]],MainTracker[[#This Row],[Comments 2 (include Date)]],MainTracker[[#This Row],[Comment 3 (include Date)]],MainTracker[[#This Row],[Comment 4 (include Date)]]),"") -> 3 | Z2: =IF(AND(MainTracker[[#This Row],[Completion date.]]>=45139,MainTracker[[#This Row],[Status]]="10 - Complete",MainTracker[[#This Row],[Compliant source file received on (Date)]]<>""),MainTracker[[#This Row],[Compliant source file received on (Date)]]-MainTracker[[#This Row],[Request sent on (Date)]],"") -> 7
A3: =_xlfn.IFNA(INDEX(Table3[],MATCH(MainTracker[[#This Row],[IDR / UFDR]],Table3[Pack],0),1),"") | B3: 236.01 | C3: HS2-00002XCBC | D3: Oxford Canal South Embankment Ditch Crossing 1 | E3: 1MC07-ASC-CV-FRM-CS07_CL23-000068-ACBOS | F3: P01 | G3: 45230 | H3: 45233 | I3: 45240 | K3: 1MC07-CEK-IM-DAT-CS07_CL23-600109 | M3: StrctrlT | O3: updated in house into SQL / Json | Q3: PW file to follow sync | U3: 10 - Complete | V3: Lee | W3: Chris Gilmour <chris.gilmour@fairhurst.co.uk> | X3: =IF(AND(MainTracker[[#This Row],[Completion date.]]>=45139,MainTracker[[#This Row],[Status]]="10 - Complete"),NETWORKDAYS(MAX(MainTracker[[#This Row],[Request sent on (Date)]:[Compliant source file received on (Date)]]),MainTracker[[#This Row],[Completion date.]],Holiday[Holidays])-1,"") -> 5 | Y3: =IF(AND(MainTracker[[#This Row],[Completion date.]]>=45139,MainTracker[[#This Row],[Status]]="10 - Complete"),COUNTA(MainTracker[[#This Row],[Comments Issued 1 (include Date)]],MainTracker[[#This Row],[Comments 2 (include Date)]],MainTracker[[#This Row],[Comment 3 (include Date)]],MainTracker[[#This Row],[Comment 4 (include Date)]]),"") -> 3 | Z3: =IF(AND(MainTracker[[#This Row],[Completion date.]]>=45139,MainTracker[[#This Row],[Status]]="10 - Complete",MainTracker[[#This Row],[Compliant source file received on (Date)]]<>""),MainTracker[[#This Row],[Compliant source file received on (Date)]]-MainTracker[[#This Row],[Request sent on (Date)]],"") -> 3
A4: =_xlfn.IFNA(INDEX(Table3[],MATCH(MainTracker[[#This Row],[IDR / UFDR]],Table3[Pack],0),1),"") | B4: 216.01 | C4: HS2-00002CT9B | D4: Charndon Lodge Pumping Station (ME) | E4: 1MC06-CEK-ME-FRM-CS06_CL09-600001 | F4: P05 | G4: 45230 | I4: 45639 | K4: 1MC06-CEK-IM-DAT-CS06_CL09-600197 | L4: No issues | M4: rvsd chacks 19-nov-24 - ZZ-ZZ class issues | N4: 45637 | O4: 92 assts - loading | Q4: LOADED - 92 | S4: 92 | U4: 10 - Complete | V4: Lee | W4: Stafford, Quincy <quincy.stafford@arcadis.com> | X4: =IF(AND(MainTracker[[#This Row],[Completion date.]]>=45139,MainTracker[[#This Row],[Status]]="10 - Complete"),NETWORKDAYS(MAX(MainTracker[[#This Row],[Request sent on (Date)]:[Compliant source file received on (Date)]]),MainTracker[[#This Row],[Completion date.]],Holiday[Holidays])-1,"") -> 282 | Y4: =IF(AND(MainTracker[[#This Row],[Completion date.]]>=45139,MainTracker[[#This Row],[Status]]="10 - Complete"),COUNTA(MainTracker[[#This Row],[Comments Issued 1 (include Date)]],MainTracker[[#This Row],[Comments 2 (include Date)]],MainTracker[[#This Row],[Comment 3 (include Date)]],MainTracker[[#This Row],[Comment 4 (include Date)]]),"") -> 4 | Z4: =IF(AND(MainTracker[[#This Row],[Completion date.]]>=45139,MainTracker[[#This Row],[Status]]="10 - Complete",MainTracker[[#This Row],[Compliant source file received on (Date)]]<>""),MainTracker[[#This Row],[Compliant source file received on (Date)]]-MainTracker[[#This Row],[Request sent on (Date)]],"")
A5: =_xlfn.IFNA(INDEX(Table3[],MATCH(MainTracker[[#This Row],[IDR / UFDR]],Table3[Pack],0),1),"") | B5: 216.01 | C5: HS2-00002CT9B | D5: Charndon Lodge Pumping Station (EL) Telecomms | E5: 1MC06-CEK-EL-FRM-CS06_CL09-600002 | F5: P06 | G5: 45230 | I5: 45639 | K5: 1MC06-CEK-IM-DAT-CS06_CL09-600197 | L5: No issues | M5: rvsd chacks 19-nov-24 - ZZ-ZZ class issues | N5: 45637 | O5: 7 loadinn g | Q5: LOADED - 7 | S5: 99 | U5: 10 - Complete | V5: Lee | W5: Stafford, Quincy <quincy.stafford@arcadis.com> | X5: =IF(AND(MainTracker[[#This Row],[Completion date.]]>=45139,MainTracker[[#This Row],[Status]]="10 - Complete"),NETWORKDAYS(MAX(MainTracker[[#This Row],[Request sent on (Date)]:[Compliant source file received on (Date)]]),MainTracker[[#This Row],[Completion date.]],Holiday[Holidays])-1,"") -> 282 | Y5: =IF(AND(MainTracker[[#This Row],[Completion date.]]>=45139,MainTracker[[#This Row],[Status]]="10 - Complete"),COUNTA(MainTracker[[#This Row],[Comments Issued 1 (include Date)]],MainTracker[[#This Row],[Comments 2 (include Date)]],MainTracker[[#This Row],[Comment 3 (include Date)]],MainTracker[[#This Row],[Comment 4 (include Date)]]),"") -> 4 | Z5: =IF(AND(MainTracker[[#This Row],[Completion date.]]>=45139,MainTracker[[#This Row],[Status]]="10 - Complete",MainTracker[[#This Row],[Compliant source file received on (Date)]]<>""),MainTracker[[#This Row],[Compliant source file received on (Date)]]-MainTracker[[#This Row],[Request sent on (Date)]],"")
A6: =_xlfn.IFNA(INDEX(Table3[],MATCH(MainTracker[[#This Row],[IDR / UFDR]],Table3[Pack],0),1),"") | B6: 216.01 | C6: HS2-00002CT9B | D6: Charndon Lodge Pumping Station (EL) | E6: 1MC06-CEK-EL-FRM-CS06_CL09-600001 | F6: P01 | G6: 45230 | I6: 45639 | K6: 1MC06-CEK-IM-DAT-CS06_CL09-600197 | L6: No issues | M6: rvsd chacks 19-nov-24 - ZZ-ZZ class issues | N6: 45637 | O6: 13 loading | Q6: LOADED 13 | S6: 112 | U6: 10 - Complete | V6: Lee | W6: Stafford, Quincy <quincy.stafford@arcadis.com> | X6: =IF(AND(MainTracker[[#This Row],[Completion date.]]>=45139,MainTracker[[#This Row],[Status]]="10 - Complete"),NETWORKDAYS(MAX(MainTracker[[#This Row],[Request sent on (Date)]:[Compliant source file received on (Date)]]),MainTracker[[#This Row],[Completion date.]],Holiday[Holidays])-1,"") -> 282 | Y6: =IF(AND(MainTracker[[#This Row],[Completion date.]]>=45139,MainTracker[[#This Row],[Status]]="10 - Complete"),COUNTA(MainTracker[[#This Row],[Comments Issued 1 (include Date)]],MainTracker[[#This Row],[Comments 2 (include Date)]],MainTracker[[#This Row],[Comment 3 (include Date)]],MainTracker[[#This Row],[Comment 4 (include Date)]]),"") -> 4 | Z6: =IF(AND(MainTracker[[#This Row],[Completion date.]]>=45139,MainTracker[[#This Row],[Status]]="10 - Complete",MainTracker[[#This Row],[Compliant source file received on (Date)]]<>""),MainTracker[[#This Row],[Compliant source file received on (Date)]]-MainTracker[[#This Row],[Request sent on (Date)]],"")
A7: =_xlfn.IFNA(INDEX(Table3[],MATCH(MainTracker[[#This Row],[IDR / UFDR]],Table3[Pack],0),1),"") | B7: 216.01 | C7: HS2-00002CT9B | D7: Charndon Lodge Pumping Station (CV) | E7: 1MC06-CEK-CV-FRM-CS06_CL09-000014 | F7: P01 | G7: 45230 | I7: 45639 | K7: 1MC06-CEK-IM-DAT-CS06_CL09-600197 | L7: No issues | M7: rvsd chacks 19-nov-24 - ZZ-ZZ class issues | N7: 45637 | O7: 59 loading | Q7: LOADED 59 | S7: 171 | U7: 10 - Complete | V7: Lee | W7: Stafford, Quincy <quincy.stafford@arcadis.com> | X7: =IF(AND(MainTracker[[#This Row],[Completion date.]]>=45139,MainTracker[[#This Row],[Status]]="10 - Complete"),NETWORKDAYS(MAX(MainTracker[[#This Row],[Request sent on (Date)]:[Compliant source file received on (Date)]]),MainTracker[[#This Row],[Completion date.]],Holiday[Holidays])-1,"") -> 282 | Y7: =IF(AND(MainTracker[[#This Row],[Completion date.]]>=45139,MainTracker[[#This Row],[Status]]="10 - Complete"),COUNTA(MainTracker[[#This Row],[Comments Issued 1 (include Date)]],MainTracker[[#This Row],[Comments 2 (include Date)]],MainTracker[[#This Row],[Comment 3 (include Date)]],MainTracker[[#This Row],[Comment 4 (include Date)]]),"") -> 4 | Z7: =IF(AND(MainTracker[[#This Row],[Completion date.]]>=45139,MainTracker[[#This Row],[Status]]="10 - Complete",MainTracker[[#This Row],[Compliant source file received on (Date)]]<>""),MainTracker[[#This Row],[Compliant source file received on (Date)]]-MainTracker[[#This Row],[Request sent on (Date)]],"")
A8: =_xlfn.IFNA(INDEX(Table3[],MATCH(MainTracker[[#This Row],[IDR / UFDR]],Table3[Pack],0),1),"") | B8: 204.3-1 | C8: HS2-00002BJS0 | D8: Nash Lee Orchard (ELL-20) Footpath Realignment | E8: 1MC06-ASC-HW-FRM-CS03_CL17-000006-ACBOS | F8: P01 | G8: 45231 | H8: 45233 | I8: 45233 | K8: 1MC06-CEK-IM-DAT-CS03_CL17-600011 | M8: some items set As None All AssetDescription_2 incorrect | U8: 10 - Complete | V8: Lee | W8: Thompson, Stephen <stephen.thompson@arcadis.com> | X8: =IF(AND(MainTracker[[#This Row],[Completion date.]]>=45139,MainTracker[[#This Row],[Status]]="10 - Complete"),NETWORKDAYS(MAX(MainTracker[[#This Row],[Request sent on (Date)]:[Compliant source file received on (Date)]]),MainTracker[[#This Row],[Completion date.]],Holiday[Holidays])-1,"") -> 0 | Y8: =IF(AND(MainTracker[[#This Row],[Completion date.]]>=45139,MainTracker[[#This Row],[Status]]="10 - Complete"),COUNTA(MainTracker[[#This Row],[Comments Issued 1 (include Date)]],MainTracker[[#This Row],[Comments 2 (include Date)]],MainTracker[[#This Row],[Comment 3 (include Date)]],MainTracker[[#This Row],[Comment 4 (include Date)]]),"") -> 1 | Z8: =IF(AND(MainTracker[[#This Row],[Completion date.]]>=45139,MainTracker[[#This Row],[Status]]="10 - Complete",MainTracker[[#This Row],[Compliant source file received on (Date)]]<>""),MainTracker[[#This Row],[Compliant source file received on (Date)]]-MainTracker[[#This Row],[Request sent on (Date)]],"") -> 2
A9: =_xlfn.IFNA(INDEX(Table3[],MATCH(MainTracker[[#This Row],[IDR / UFDR]],Table3[Pack],0),1),"") | B9: 236.01 | C9: HS2-00003B585 | D9: Oxford Canal South Embankment Ditch Crossing 2 | E9: 1MC07-ASC-CV-FRM-CS07_CL23-000069-ACBOS | F9: P01 | G9: 45231 | H9: 45233 | I9: 45240 | K9: 1MC07-CEK-IM-DAT-CS07_CL23-600110 | M9: StrctrlT | O9: updated in house into SQL / Json | Q9: PW file to follow sync | U9: 10 - Complete | V9: Lee | W9: Chris Gilmour <chris.gilmour@fairhurst.co.uk> | X9: =IF(AND(MainTracker[[#This Row],[Completion date.]]>=45139,MainTracker[[#This Row],[Status]]="10 - Complete"),NETWORKDAYS(MAX(MainTracker[[#This Row],[Request sent on (Date)]:[Compliant source file received on (Date)]]),MainTracker[[#This Row],[Completion date.]],Holiday[Holidays])-1,"") -> 5 | Y9: =IF(AND(MainTracker[[#This Row],[Completion date.]]>=45139,MainTracker[[#This Row],[Status]]="10 - Complete"),COUNTA(MainTracker[[#This Row],[Comments Issued 1 (include Date)]],MainTracker[[#This Row],[Comments 2 (include Date)]],MainTracker[[#This Row],[Comment 3 (include Date)]],MainTracker[[#This Row],[Comment 4 (include Date)]]),"") -> 3 | Z9: =IF(AND(MainTracker[[#This Row],[Completion date.]]>=45139,MainTracker[[#This Row],[Status]]="10 - Complete",MainTracker[[#This Row],[Compliant source file received on (Date)]]<>""),MainTracker[[#This Row],[Compliant source file received on (Date)]]-MainTracker[[#This Row],[Request sent on (Date)]],"") -> 2
A10: =_xlfn.IFNA(INDEX(Table3[],MATCH(MainTracker[[#This Row],[IDR / UFDR]],Table3[Pack],0),1),"") | B10: 216.01-2 | C10: HS2-00002CT8U | D10: HS2-00002C5T4-West Street Drainage System | E10: 1MC06-ASC-DR-FRM-CS06_CL09-000029-ACBOS | F10: P01 | G10: 45232 | H10: 45233 | I10: 45236 | K10: 1MC06-CEK-IM-DAT-CS06_CL09-600255 | M10: 2 DsgnFlw att set to 0 - DT to fix | U10: 10 - Complete | V10: Lee | W10: Rai C, Keerthan <keerthan.raic@arcadis.com> | X10: =IF(AND(MainTracker[[#This Row],[Completion date.]]>=45139,MainTracker[[#This Row],[Status]]="10 - Complete"),NETWORKDAYS(MAX(MainTracker[[#This Row],[Request sent on (Date)]:[Compliant source file received on (Date)]]),MainTracker[[#This Row],[Completion date.]],Holiday[Holidays])-1,"") -> 1 | Y10: =IF(AND(MainTracker[[#This Row],[Completion date.]]>=45139,MainTracker[[#This Row],[Status]]="10 - Complete"),COUNTA(MainTracker[[#This Row],[Comments Issued 1 (include Date)]],MainTracker[[#This Row],[Comments 2 (include Date)]],MainTracker[[#This Row],[Comment 3 (include Date)]],MainTracker[[#This Row],[Comment 4 (include Date)]]),"") -> 1 | Z10: =IF(AND(MainTracker[[#This Row],[Completion date.]]>=45139,MainTracker[[#This Row],[Status]]="10 - Complete",MainTracker[[#This Row],[Compliant source file received on (Date)]]<>""),MainTracker[[#This Row],[Compliant source file received on (Date)]]-MainTracker[[#This Row],[Request sent on (Date)]],"") -> 1
A11: =_xlfn.IFNA(INDEX(Table3[],MATCH(MainTracker[[#This Row],[IDR / UFDR]],Table3[Pack],0),1),"") | B11: 230.01 | C11: HS2-00002PRWV | D11: Lower Thorpe Viaduct Group | E11: 1MC07-ASC-CV-FRM-CS07_CL26-000069-ACBOS | F11: P01 | G11: 45232 | I11: 45237 | K11: 1MC07-CEK-IM-DAT-CS07_CL26-600131 | U11: 10 - Complete | V11: Supriyan | W11: PATIL, APOORVA <apoorva.patil@arcadis.com> | X11: =IF(AND(MainTracker[[#This Row],[Completion date.]]>=45139,MainTracker[[#This Row],[Status]]="10 - Complete"),NETWORKDAYS(MAX(MainTracker[[#This Row],[Request sent on (Date)]:[Compliant source file received on (Date)]]),MainTracker[[#This Row],[Completion date.]],Holiday[Holidays])-1,"") -> 3 | Y11: =IF(AND(MainTracker[[#This Row],[Completion date.]]>=45139,MainTracker[[#This Row],[Status]]="10 - Complete"),COUNTA(MainTracker[[#This Row],[Comments Issued 1 (include Date)]],MainTracker[[#This Row],[Comments 2 (include Date)]],MainTracker[[#This Row],[Comment 3 (include Date)]],MainTracker[[#This Row],[Comment 4 (include Date)]]),"") -> 0 | Z11: =IF(AND(MainTracker[[#This Row],[Completion date.]]>=45139,MainTracker[[#This Row],[Status]]="10 - Complete",MainTracker[[#This Row],[Compliant source file received on (Date)]]<>""),MainTracker[[#This Row],[Compliant source file received on (Date)]]-MainTracker[[#This Row],[Request sent on (Date)]],"")
A12: =_xlfn.IFNA(INDEX(Table3[],MATCH(MainTracker[[#This Row],[IDR / UFDR]],Table3[Pack],0),1),"") | B12: 223.4 | C12: HS2-00002BJV0 | D12: Bridleway 303/4 and 303/22 Diversions | E12: 1MC06-ASC-HW-FRM-CS06_CL22-000015-ACBOS | F12: P01 | G12: 45232 | H12: 45237 | I12: 45239 | K12: 1MC06-CEK-IM-DAT-CS06_CL22-600110 | M12: Send Queries to Team on 07-Nov-23 | U12: 10 - Complete | V12: Supriyan | W12: MIRI Youssef <youssef.miri@setec.com> | X12: =IF(AND(MainTracker[[#This Row],[Completion date.]]>=45139,MainTracker[[#This Row],[Status]]="10 - Complete"),NETWORKDAYS(MAX(MainTracker[[#This Row],[Request sent on (Date)]:[Compliant source file received on (Date)]]),MainTracker[[#This Row],[Completion date.]],Holiday[Holidays])-1,"") -> 2 | Y12: =IF(AND(MainTracker[[#This Row],[Completion date.]]>=45139,MainTracker[[#This Row],[Status]]="10 - Complete"),COUNTA(MainTracker[[#This Row],[Comments Issued 1 (include Date)]],MainTracker[[#This Row],[Comments 2 (include Date)]],MainTracker[[#This Row],[Comment 3 (include Date)]],MainTracker[[#This Row],[Comment 4 (include Date)]]),"") -> 1 | Z12: =IF(AND(MainTracker[[#This Row],[Completion date.]]>=45139,MainTracker[[#This Row],[Status]]="10 - Complete",MainTracker[[#This Row],[Compliant source file received on (Date)]]<>""),MainTracker[[#This Row],[Compliant source file received on (Date)]]-MainTracker[[#This Row],[Request sent on (Date)]],"") -> 5
A13: =_xlfn.IFNA(INDEX(Table3[],MATCH(MainTracker[[#This Row],[IDR / UFDR]],Table3[Pack],0),1),"") | B13: 223.4 | C13: HS2-00002BJV1 | D13: Maintenance Access Road to Pond (Off Bridleway 303/4) 01 | E13: 1MC06-ASC-HW-FRM-CS06_CL22-000009-ACBOS | F13: P01 | G13: 45232 | H13: 45237 | I13: 45240 | K13: 1MC06-CEK-IM-DAT-CS06_CL22-600080 | M13: Send Queries to Team on 07-Nov-23 | U13: 10 - Complete | V13: Supriyan | W13: MIRI Youssef <youssef.miri@setec.com> | X13: =IF(AND(MainTracker[[#This Row],[Completion date.]]>=45139,MainTracker[[#This Row],[Status]]="10 - Complete"),NETWORKDAYS(MAX(MainTracker[[#This Row],[Request sent on (Date)]:[Compliant source file received on (Date)]]),MainTracker[[#This Row],[Completion date.]],Holiday[Holidays])-1,"") -> 3 | Y13: =IF(AND(MainTracker[[#This Row],[Completion date.]]>=45139,MainTracker[[#This Row],[Status]]="10 - Complete"),COUNTA(MainTracker[[#This Row],[Comments Issued 1 (include Date)]],MainTracker[[#This Row],[Comments 2 (include Date)]],MainTracker[[#This Row],[Comment 3 (include Date)]],MainTracker[[#This Row],[Comment 4 (include Date)]]),"") -> 1 | Z13: =IF(AND(MainTracker[[#This Row],[Completion date.]]>=45139,MainTracker[[#This Row],[Status]]="10 - Complete",MainTracker[[#This Row],[Compliant source file received on (Date)]]<>""),MainTracker[[#This Row],[Compliant source file received on (Date)]]-MainTracker[[#This Row],[Request sent on (Date)]],"") -> 5
A14: =_xlfn.IFNA(INDEX(Table3[],MATCH(MainTracker[[#This Row],[IDR / UFDR]],Table3[Pack],0),1),"") | B14: 223.4 | C14: HS2-00002BJV2 | D14: Maintenance Access Road to Pond (Off Bridleway 303/4) 02 | E14: 1MC06-ASC-HW-FRM-CS06_CL22-000010-ACBOS | F14: P01 | G14: 45232 | H14: 45237 | I14: 45246 | K14: 1MC06-CEK-IM-DAT-CS06_CL22-600081 | M14: Send Queries to Team on 07-Nov-23 | U14: 10 - Complete | V14: Supriyan | W14: MIRI Youssef <youssef.miri@setec.com> | X14: =IF(AND(MainTracker[[#This Row],[Completion date.]]>=45139,MainTracker[[#This Row],[Status]]="10 - Complete"),NETWORKDAYS(MAX(MainTracker[[#This Row],[Request sent on (Date)]:[Compliant source file received on (Date)]]),MainTracker[[#This Row],[Completion date.]],Holiday[Holidays])-1,"") -> 7 | Y14: =IF(AND(MainTracker[[#This Row],[Completion date.]]>=45139,MainTracker[[#This Row],[Status]]="10 - Complete"),COUNTA(MainTracker[[#This Row],[Comments Issued 1 (include Date)]],MainTracker[[#This Row],[Comments 2 (include Date)]],MainTracker[[#This Row],[Comment 3 (include Date)]],MainTracker[[#This Row],[Comment 4 (include Date)]]),"") -> 1 | Z14: =IF(AND(MainTracker[[#This Row],[Completion date.]]>=45139,MainTracker[[#This Row],[Status]]="10 - Complete",MainTracker[[#This Row],[Compliant source file received on (Date)]]<>""),MainTracker[[#This Row],[Compliant source file received on (Date)]]-MainTracker[[#This Row],[Request sent on (Date)]],"") -> 5
A15: =_xlfn.IFNA(INDEX(Table3[],MATCH(MainTracker[[#This Row],[IDR / UFDR]],Table3[Pack],0),1),"") | B15: 223.4 | C15: HS2-00002BJV3 | D15: Bridleway 303/5 Link | E15: 1MC06-ASC-HW-FRM-CS06_CL22-900011-ACBOS | F15: P01 | G15: 45232 | H15: 45237 | I15: 45239 | K15: 1MC06-CEK-IM-DAT-CS06_CL22-600087 | M15: Send Queries to Team on 07-Nov-23 | U15: 10 - Complete | V15: Supriyan | W15: MIRI Youssef <youssef.miri@setec.com> | X15: =IF(AND(MainTracker[[#This Row],[Completion date.]]>=45139,MainTracker[[#This Row],[Status]]="10 - Complete"),NETWORKDAYS(MAX(MainTracker[[#This Row],[Request sent on (Date)]:[Compliant source file received on (Date)]]),MainTracker[[#This Row],[Completion date.]],Holiday[Holidays])-1,"") -> 2 | Y15: =IF(AND(MainTracker[[#This Row],[Completion date.]]>=45139,MainTracker[[#This Row],[Status]]="10 - Complete"),COUNTA(MainTracker[[#This Row],[Comments Issued 1 (include Date)]],MainTracker[[#This Row],[Comments 2 (include Date)]],MainTracker[[#This Row],[Comment 3 (include Date)]],MainTracker[[#This Row],[Comment 4 (include Date)]]),"") -> 1 | Z15: =IF(AND(MainTracker[[#This Row],[Completion date.]]>=45139,MainTracker[[#This Row],[Status]]="10 - Complete",MainTracker[[#This Row],[Compliant source file received on (Date)]]<>""),MainTracker[[#This Row],[Compliant source file received on (Date)]]-MainTracker[[#This Row],[Request sent on (Date)]],"") -> 5
A16: =_xlfn.IFNA(INDEX(Table3[],MATCH(MainTracker[[#This Row],[IDR / UFDR]],Table3[Pack],0),1),"") | B16: 223.4 | C16: HS2-00002J4YM | D16: Bridleway 303/4 Accommodation Access Realignment | E16: 1MC06-ASC-HW-FRM-CS06_CL22-900005-ACBOS | F16: P01 | G16: 45232 | H16: 45237 | I16: 45259 | K16: 1MC06-CEK-IM-DAT-CS06_CL22-600039 | M16: Send Queries to Team on 07-Nov-23 | U16: 10 - Complete | V16: Supriyan | W16: MIRI Youssef <youssef.miri@setec.com> | X16: =IF(AND(MainTracker[[#This Row],[Completion date.]]>=45139,MainTracker[[#This Row],[Status]]="10 - Complete"),NETWORKDAYS(MAX(MainTracker[[#This Row],[Request sent on (Date)]:[Compliant source file received on (Date)]]),MainTracker[[#This Row],[Completion date.]],Holiday[Holidays])-1,"") -> 16 | Y16: =IF(AND(MainTracker[[#This Row],[Completion date.]]>=45139,MainTracker[[#This Row],[Status]]="10 - Complete"),COUNTA(MainTracker[[#This Row],[Comments Issued 1 (include Date)]],MainTracker[[#This Row],[Comments 2 (include Date)]],MainTracker[[#This Row],[Comment 3 (include Date)]],MainTracker[[#This Row],[Comment 4 (include Date)]]),"") -> 1 | Z16: =IF(AND(MainTracker[[#This Row],[Completion date.]]>=45139,MainTracker[[#This Row],[Status]]="10 - Complete",MainTracker[[#This Row],[Compliant source file received on (Date)]]<>""),MainTracker[[#This Row],[Compliant source file received on (Date)]]-MainTracker[[#This Row],[Request sent on (Date)]],"") -> 5
A17: =_xlfn.IFNA(INDEX(Table3[],MATCH(MainTracker[[#This Row],[IDR / UFDR]],Table3[Pack],0),1),"") | B17: 235.01-1 | C17: HS2-000001456 | D17: Footpath SM101 Green Overbridge | E17: 1MC07-ASC-BR-FRM-CS07_CL14-000002-ACBOS | F17: P02 | G17: 45237 | I17: 45244 | K17: 1MC07-CEK-IM-DAT-CS07_CL14-600018 | M17: FAIL - close to zero rebar - DT investigating - MONDAY | O17: revised file rcvd 13-11-23 | U17: 10 - Complete | V17: Lee | W17: Kumar, M Praveen <mpraveen.kumar@arcadis.com> | X17: =IF(AND(MainTracker[[#This Row],[Completion date.]]>=45139,MainTracker[[#This Row],[Status]]="10 - Complete"),NETWORKDAYS(MAX(MainTracker[[#This Row],[Request sent on (Date)]:[Compliant source file received on (Date)]]),MainTracker[[#This Row],[Completion date.]],Holiday[Holidays])-1,"") -> 5 | Y17: =IF(AND(MainTracker[[#This Row],[Completion date.]]>=45139,MainTracker[[#This Row],[Status]]="10 - Complete"),COUNTA(MainTracker[[#This Row],[Comments Issued 1 (include Date)]],MainTracker[[#This Row],[Comments 2 (include Date)]],MainTracker[[#This Row],[Comment 3 (include Date)]],MainTracker[[#This Row],[Comment 4 (include Date)]]),"") -> 2 | Z17: =IF(AND(MainTracker[[#This Row],[Completion date.]]>=45139,MainTracker[[#This Row],[Status]]="10 - Complete",MainTracker[[#This Row],[Compliant source file received on (Date)]]<>""),MainTracker[[#This Row],[Compliant source file received on (Date)]]-MainTracker[[#This Row],[Request sent on (Date)]],"")
A18: =_xlfn.IFNA(INDEX(Table3[],MATCH(MainTracker[[#This Row],[IDR / UFDR]],Table3[Pack],0),1),"") | B18: 237.02 | C18: HS2-00002EL0S | D18: C3.L.81 Catchment | E18: 1MC07-ASC-DR-FRM-CS07_CL23-000022-ACBOS | F18: P02 | G18: 45237 | I18: 45238 | K18: 1MC07-CEK-IM-DAT-CS07_CL23-600019 | U18: 10 - Complete | V18: Supriyan | W18: B, Gopika <gopika.b@arcadis.com> | X18: =IF(AND(MainTracker[[#This Row],[Completion date.]]>=45139,MainTracker[[#This Row],[Status]]="10 - Complete"),NETWORKDAYS(MAX(MainTracker[[#This Row],[Request sent on (Date)]:[Compliant source file received on (Date)]]),MainTracker[[#This Row],[Completion date.]],Holiday[Holidays])-1,"") -> 1 | Y18: =IF(AND(MainTracker[[#This Row],[Completion date.]]>=45139,MainTracker[[#This Row],[Status]]="10 - Complete"),COUNTA(MainTracker[[#This Row],[Comments Issued 1 (include Date)]],MainTracker[[#This Row],[Comments 2 (include Date)]],MainTracker[[#This Row],[Comment 3 (include Date)]],MainTracker[[#This Row],[Comment 4 (include Date)]]),"") -> 0 | Z18: =IF(AND(MainTracker[[#This Row],[Completion date.]]>=45139,MainTracker[[#This Row],[Status]]="10 - Complete",MainTracker[[#This Row],[Compliant source file received on (Date)]]<>""),MainTracker[[#This Row],[Compliant source file received on (Date)]]-MainTracker[[#This Row],[Request sent on (Date)]],"")
A19: =_xlfn.IFNA(INDEX(Table3[],MATCH(MainTracker[[#This Row],[IDR / UFDR]],Table3[Pack],0),1),"") | B19: 237.02 | C19: HS2-00002CTJT | D19: C3.T.70 Catchment | E19: 1MC07-ASC-DR-FRM-CS07_CL23-000004-ACBOS | F19: P01 | G19: 45237 | H19: 45237 | I19: 45238 | K19: 1MC07-CEK-IM-DAT-CS07_CL23-600059 | U19: 10 - Complete | V19: Lee | W19: B, Gopika <gopika.b@arcadis.com> | X19: =IF(AND(MainTracker[[#This Row],[Completion date.]]>=45139,MainTracker[[#This Row],[Status]]="10 - Complete"),NETWORKDAYS(MAX(MainTracker[[#This Row],[Request sent on (Date)]:[Compliant source file received on (Date)]]),MainTracker[[#This Row],[Completion date.]],Holiday[Holidays])-1,"") -> 1 | Y19: =IF(AND(MainTracker[[#This Row],[Completion date.]]>=45139,MainTracker[[#This Row],[Status]]="10 - Complete"),COUNTA(MainTracker[[#This Row],[Comments Issued 1 (include Date)]],MainTracker[[#This Row],[Comments 2 (include Date)]],MainTracker[[#This Row],[Comment 3 (include Date)]],MainTracker[[#This Row],[Comment 4 (include Date)]]),"") -> 0 | Z19: =IF(AND(MainTracker[[#This Row],[Completion date.]]>=45139,MainTracker[[#This Row],[Status]]="10 - Complete",MainTracker[[#This Row],[Compliant source file received on (Date)]]<>""),MainTracker[[#This Row],[Compliant source file received on (Date)]]-MainTracker[[#This Row],[Request sent on (Date)]],"") -> 0
A20: =_xlfn.IFNA(INDEX(Table3[],MATCH(MainTracker[[#This Row],[IDR / UFDR]],Table3[Pack],0),1),"") | B20: 218.02-1 | C20: HS2-00002KRAM | D20: IMD East Culvert Watercourse Diversion | E20: 1MC06-ASC-DR-FRM-CS06_CL09-000097-ACBOS | F20: P02 | G20: 45238 | H20: 45239 | I20: 45240 | K20: 1MC06-CEK-IM-DAT-CS06_CL09-600166 | U20: 10 - Complete | V20: Lee | W20: Somashekar, Yashwanth KumarS <YashwanthKumar.S.Somashekar@arcadis.com> | X20: =IF(AND(MainTracker[[#This Row],[Completion date.]]>=45139,MainTracker[[#This Row],[Status]]="10 - Complete"),NETWORKDAYS(MAX(MainTracker[[#This Row],[Request sent on (Date)]:[Compliant source file received on (Date)]]),MainTracker[[#This Row],[Completion date.]],Holiday[Holidays])-1,"") -> 1 | Y20: =IF(AND(MainTracker[[#This Row],[Completion date.]]>=45139,MainTracker[[#This Row],[Status]]="10 - Complete"),COUNTA(MainTracker[[#This Row],[Comments Issued 1 (include Date)]],MainTracker[[#This Row],[Comments 2 (include Date)]],MainTracker[[#This Row],[Comment 3 (include Date)]],MainTracker[[#This Row],[Comment 4 (include Date)]]),"") -> 0 | Z20: =IF(AND(MainTracker[[#This Row],[Completion date.]]>=45139,MainTracker[[#This Row],[Status]]="10 - Complete",MainTracker[[#This Row],[Compliant source file received on (Date)]]<>""),MainTracker[[#This Row],[Compliant source file received on (Date)]]-MainTracker[[#This Row],[Request sent on (Date)]],"") -> 1
A21: =_xlfn.IFNA(INDEX(Table3[],MATCH(MainTracker[[#This Row],[IDR / UFDR]],Table3[Pack],0),1),"") | B21: 220.5 | C21: HS2-00002BJUL | D21: Maintenance Access Road MAP (Bridleway CHW/24 Upgrade) | E21: 1MC06-ASC-HW-FRM-CS06_CL10-900029-ACBOS | F21: P02 | G21: 45238 | H21: 45254 | I21: 45257 | K21: 1MC06-CEK-IM-DAT-CS06_CL10-600089 | M21: DT revising file based on LodG 22-11-23 | O21: DT reworking model. Barriers / post issues | U21: 10 - Complete | V21: Supriyan | W21: KHABOUZE Zakaria <zakaria.khabouze@setec.com> | X21: =IF(AND(MainTracker[[#This Row],[Completion date.]]>=45139,MainTracker[[#This Row],[Status]]="10 - Complete"),NETWORKDAYS(MAX(MainTracker[[#This Row],[Request sent on (Date)]:[Compliant source file received on (Date)]]),MainTracker[[#This Row],[Completion date.]],Holiday[Holidays])-1,"") -> 1 | Y21: =IF(AND(MainTracker[[#This Row],[Completion date.]]>=45139,MainTracker[[#This Row],[Status]]="10 - Complete"),COUNTA(MainTracker[[#This Row],[Comments Issued 1 (include Date)]],MainTracker[[#This Row],[Comments 2 (include Date)]],MainTracker[[#This Row],[Comment 3 (include Date)]],MainTracker[[#This Row],[Comment 4 (include Date)]]),"") -> 2 | Z21: =IF(AND(MainTracker[[#This Row],[Completion date.]]>=45139,MainTracker[[#This Row],[Status]]="10 - Complete",MainTracker[[#This Row],[Compliant source file received on (Date)]]<>""),MainTracker[[#This Row],[Compliant source file received on (Date)]]-MainTracker[[#This Row],[Request sent on (Date)]],"") -> 16
A22: =_xlfn.IFNA(INDEX(Table3[],MATCH(MainTracker[[#This Row],[IDR / UFDR]],Table3[Pack],0),1),"") | B22: 220.5 | C22: HS2-00002BJUM | D22: Maintenance Access Road to Pond and MAP (Footpath 225-4 Upgrade) | E22: 1MC06-ASC-HW-FRM-CS06_CL10-000024-ACBOS | F22: P01 | G22: 45238 | H22: 45240 | I22: 45243 | K22: 1MC06-CEK-IM-DAT-CS06_CL10-600084 | M22: DT HAVE MADE CHANGES AND REISSUED | U22: 10 - Complete | V22: Lee | W22: KHABOUZE Zakaria <zakaria.khabouze@setec.com> | X22: =IF(AND(MainTracker[[#This Row],[Completion date.]]>=45139,MainTracker[[#This Row],[Status]]="10 - Complete"),NETWORKDAYS(MAX(MainTracker[[#This Row],[Request sent on (Date)]:[Compliant source file received on (Date)]]),MainTracker[[#This Row],[Completion date.]],Holiday[Holidays])-1,"") -> 1 | Y22: =IF(AND(MainTracker[[#This Row],[Completion date.]]>=45139,MainTracker[[#This Row],[Status]]="10 - Complete"),COUNTA(MainTracker[[#This Row],[Comments Issued 1 (include Date)]],MainTracker[[#This Row],[Comments 2 (include Date)]],MainTracker[[#This Row],[Comment 3 (include Date)]],MainTracker[[#This Row],[Comment 4 (include Date)]]),"") -> 1 | Z22: =IF(AND(MainTracker[[#This Row],[Completion date.]]>=45139,MainTracker[[#This Row],[Status]]="10 - Complete",MainTracker[[#This Row],[Compliant source file received on (Date)]]<>""),MainTracker[[#This Row],[Compliant source file received on (Date)]]-MainTracker[[#This Row],[Request sent on (Date)]],"") -> 2
A23: =_xlfn.IFNA(INDEX(Table3[],MATCH(MainTracker[[#This Row],[IDR / UFDR]],Table3[Pack],0),1),"") | B23: 220.5 | C23: HS2-00002J4YG | D23: Bridleway CHW/24 Link | E23: 1MC06-ASC-HW-FRM-CS06_CL10-000022-ACBOS | F23: P01 - still | G23: 45238 | H23: 45244 | I23: 45245 | K23: 1MC06-CEK-IM-DAT-CS06_CL10-600054 | M23: DT HAVE MADE CHANGES AND REISSUED | U23: 10 - Complete | V23: Lee | W23: KHABOUZE Zakaria <zakaria.khabouze@setec.com> | X23: =IF(AND(MainTracker[[#This Row],[Completion date.]]>=45139,MainTracker[[#This Row],[Status]]="10 - Complete"),NETWORKDAYS(MAX(MainTracker[[#This Row],[Request sent on (Date)]:[Compliant source file received on (Date)]]),MainTracker[[#This Row],[Completion date.]],Holiday[Holidays])-1,"") -> 1 | Y23: =IF(AND(MainTracker[[#This Row],[Completion date.]]>=45139,MainTracker[[#This Row],[Status]]="10 - Complete"),COUNTA(MainTracker[[#This Row],[Comments Issued 1 (include Date)]],MainTracker[[#This Row],[Comments 2 (include Date)]],MainTracker[[#This Row],[Comment 3 (include Date)]],MainTracker[[#This Row],[Comment 4 (include Date)]]),"") -> 1 | Z23: =IF(AND(MainTracker[[#This Row],[Completion date.]]>=45139,MainTracker[[#This Row],[Status]]="10 - Complete",MainTracker[[#This Row],[Compliant source file received on (Date)]]<>""),MainTracker[[#This Row],[Compliant source file received on (Date)]]-MainTracker[[#This Row],[Request sent on (Date)]],"") -> 6
A24: =_xlfn.IFNA(INDEX(Table3[],MATCH(MainTracker[[#This Row],[IDR / UFDR]],Table3[Pack],0),1),"") | B24: 209.2-3 | C24: HS2-00002CT64 | D24: River Thame Watercourse Diversion | E24: 1MC06-ASC-DR-FRM-CS04_CL19-000044-ACBOS | F24: P04 | G24: 45239 | H24: 45246 | I24: 45247 | K24: 1MC06-CEK-IM-DAT-CS04_CL19-600001 | M24: revised file rcvd 16-nov-23 | U24: 10 - Complete | V24: Lee | W24: SS, Saravanakumar <saravanakumar.ss@arcadis.com> | X24: =IF(AND(MainTracker[[#This Row],[Completion date.]]>=45139,MainTracker[[#This Row],[Status]]="10 - Complete"),NETWORKDAYS(MAX(MainTracker[[#This Row],[Request sent on (Date)]:[Compliant source file received on (Date)]]),MainTracker[[#This Row],[Completion date.]],Holiday[Holidays])-1,"") -> 1 | Y24: =IF(AND(MainTracker[[#This Row],[Completion date.]]>=45139,MainTracker[[#This Row],[Status]]="10 - Complete"),COUNTA(MainTracker[[#This Row],[Comments Issued 1 (include Date)]],MainTracker[[#This Row],[Comments 2 (include Date)]],MainTracker[[#This Row],[Comment 3 (include Date)]],MainTracker[[#This Row],[Comment 4 (include Date)]]),"") -> 1 | Z24: =IF(AND(MainTracker[[#This Row],[Completion date.]]>=45139,MainTracker[[#This Row],[Status]]="10 - Complete",MainTracker[[#This Row],[Compliant source file received on (Date)]]<>""),MainTracker[[#This Row],[Compliant source file received on (Date)]]-MainTracker[[#This Row],[Request sent on (Date)]],"") -> 7
A25: =_xlfn.IFNA(INDEX(Table3[],MATCH(MainTracker[[#This Row],[IDR / UFDR]],Table3[Pack],0),1),"") | B25: 202.4-4 | C25: HS2-00002U7JY | D25: Rocky Lane Ditch Slab | E25: 1MC06-ASC-CV-FRM-CS03_CL05-000056-ACBOS | F25: P01 | G25: 45239 | H25: 45244 | I25: 45244 | K25: 1MC06-CEK-IM-DAT-CS03_CL05-600160 | M25: Send back on 13-Nov-23, few mismatch w.r.t MPDT | U25: 10 - Complete | V25: Supriyan | W25: S, Supreeth <Supreeth.S@arcadis.com> & Tilici, Andreea <andreea.tilici@arcadis.com> | X25: =IF(AND(MainTracker[[#This Row],[Completion date.]]>=45139,MainTracker[[#This Row],[Status]]="10 - Complete"),NETWORKDAYS(MAX(MainTracker[[#This Row],[Request sent on (Date)]:[Compliant source file received on (Date)]]),MainTracker[[#This Row],[Completion date.]],Holiday[Holidays])-1,"") -> 0 | Y25: =IF(AND(MainTracker[[#This Row],[Completion date.]]>=45139,MainTracker[[#This Row],[Status]]="10 - Complete"),COUNTA(MainTracker[[#This Row],[Comments Issued 1 (include Date)]],MainTracker[[#This Row],[Comments 2 (include Date)]],MainTracker[[#This Row],[Comment 3 (include Date)]],MainTracker[[#This Row],[Comment 4 (include Date)]]),"") -> 1 | Z25: =IF(AND(MainTracker[[#This Row],[Completion date.]]>=45139,MainTracker[[#This Row],[Status]]="10 - Complete",MainTracker[[#This Row],[Compliant source file received on (Date)]]<>""),MainTracker[[#This Row],[Compliant source file received on (Date)]]-MainTracker[[#This Row],[Request sent on (Date)]],"") -> 5
A26: =_xlfn.IFNA(INDEX(Table3[],MATCH(MainTracker[[#This Row],[IDR / UFDR]],Table3[Pack],0),1),"") | B26: 223.4 | C26: HS2-00002VNJ2 | D26: Westbury Embankment - Ancillary Culvert 092 - AC2 | E26: 1MC06-ASC-DR-FRM-CS06_CL22-000039-ACBOS | F26: P01 | G26: 45239 | I26: 45244 | K26: 1MC06-CEK-IM-DAT-CS06_CL22-600119 | U26: 10 - Complete | V26: Supriyan | W26: MIRI Youssef <youssef.miri@setec.com> | X26: =IF(AND(MainTracker[[#This Row],[Completion date.]]>=45139,MainTracker[[#This Row],[Status]]="10 - Complete"),NETWORKDAYS(MAX(MainTracker[[#This Row],[Request sent on (Date)]:[Compliant source file received on (Date)]]),MainTracker[[#This Row],[Completion date.]],Holiday[Holidays])-1,"") -> 3 | Y26: =IF(AND(MainTracker[[#This Row],[Completion date.]]>=45139,MainTracker[[#This Row],[Status]]="10 - Complete"),COUNTA(MainTracker[[#This Row],[Comments Issued 1 (include Date)]],MainTracker[[#This Row],[Comments 2 (include Date)]],MainTracker[[#This Row],[Comment 3 (include Date)]],MainTracker[[#This Row],[Comment 4 (include Date)]]),"") -> 0 | Z26: =IF(AND(MainTracker[[#This Row],[Completion date.]]>=45139,MainTracker[[#This Row],[Status]]="10 - Complete",MainTracker[[#This Row],[Compliant source file received on (Date)]]<>""),MainTracker[[#This Row],[Compliant source file received on (Date)]]-MainTracker[[#This Row],[Request sent on (Date)]],"")
A27: =_xlfn.IFNA(INDEX(Table3[],MATCH(MainTracker[[#This Row],[IDR / UFDR]],Table3[Pack],0),1),"") | B27: 223.4 | C27: HS2-00002BVJ7 | D27: C2.L.104 Catchment | E27: 1MC06-ASC-DR-FRM-CS06_CL22-000004-ACBOS | F27: P01.1 | G27: 45240 | I27: 45259 | K27: 1MC06-CEK-IM-DAT-CS06_CL22-600088 | U27: 10 - Complete | V27: Supriyan | W27: KOUEKAM NASSI Gladys Flora <gladys.kouekam-nassi@setec.com> | X27: =IF(AND(MainTracker[[#This Row],[Completion date.]]>=45139,MainTracker[[#This Row],[Status]]="10 - Complete"),NETWORKDAYS(MAX(MainTracker[[#This Row],[Request sent on (Date)]:[Compliant source file received on (Date)]]),MainTracker[[#This Row],[Completion date.]],Holiday[Holidays])-1,"") -> 13 | Y27: =IF(AND(MainTracker[[#This Row],[Completion date.]]>=45139,MainTracker[[#This Row],[Status]]="10 - Complete"),COUNTA(MainTracker[[#This Row],[Comments Issued 1 (include Date)]],MainTracker[[#This Row],[Comments 2 (include Date)]],MainTracker[[#This Row],[Comment 3 (include Date)]],MainTracker[[#This Row],[Comment 4 (include Date)]]),"") -> 0 | Z27: =IF(AND(MainTracker[[#This Row],[Completion date.]]>=45139,MainTracker[[#This Row],[Status]]="10 - Complete",MainTracker[[#This Row],[Compliant source file received on (Date)]]<>""),MainTracker[[#This Row],[Compliant source file received on (Date)]]-MainTracker[[#This Row],[Request sent on (Date)]],"")
