Workbook

Sheet Sheet1
A1: Level 2 UAID | B1: Level 2 Asset Name | C1: MPDT
A2: HS2-00003CPX7 | B2: Doddershall Embankment Planting Plot 9 | C2: =INDEX('MPDT(star) in EV'!A:A,MATCH(B2,'MPDT(star) in EV'!C:C,0)) -> 1MC06-CEK-EV-FRM-CS05-600010
A3: HS2-00003CPX6 | B3: Doddershall Embankment Planting Plot 8 | C3: =INDEX('MPDT(star) in EV'!A:A,MATCH(B3,'MPDT(star) in EV'!C:C,0)) -> 1MC06-CEK-EV-FRM-CS05-600009
A4: HS2-00003CPX4 | B4: Doddershall Embankment Planting Plot 7 | C4: =INDEX('MPDT(star) in EV'!A:A,MATCH(B4,'MPDT(star) in EV'!C:C,0)) -> 1MC06-CEK-EV-FRM-CS05-600008
A5: HS2-00003CPX3 | B5: Doddershall Embankment Planting Plot 6 | C5: =INDEX('MPDT(star) in EV'!A:A,MATCH(B5,'MPDT(star) in EV'!C:C,0)) -> 1MC06-CEK-EV-FRM-CS05-600007
A6: HS2-00003CPX2 | B6: Doddershall Embankment Planting Plot 5 | C6: =INDEX('MPDT(star) in EV'!A:A,MATCH(B6,'MPDT(star) in EV'!C:C,0)) -> 1MC06-CEK-EV-FRM-CS05-600006
A7: HS2-00003CPX1 | B7: Doddershall Embankment Planting Plot 4 | C7: =INDEX('MPDT(star) in EV'!A:A,MATCH(B7,'MPDT(star) in EV'!C:C,0)) -> 1MC06-CEK-EV-FRM-CS05-600005
A8: HS2-00003CPWZ | B8: Doddershall Embankment Planting Plot 3 | C8: =INDEX('MPDT(star) in EV'!A:A,MATCH(B8,'MPDT(star) in EV'!C:C,0)) -> 1MC06-CEK-EV-FRM-CS05-600004
A9: HS2-00003CPWY | B9: Doddershall Embankment Planting Plot 2 | C9: =INDEX('MPDT(star) in EV'!A:A,MATCH(B9,'MPDT(star) in EV'!C:C,0)) -> 1MC06-CEK-EV-FRM-CS05-600003
A10: HS2-00003CPWX | B10: Doddershall Embankment Planting Plot 1 | C10: =INDEX('MPDT(star) in EV'!A:A,MATCH(B10,'MPDT(star) in EV'!C:C,0)) -> 1MC06-CEK-EV-FRM-CS05-600002
A11: HS2-00002WUML | B11: Whaddon Hill Cutting Planting-West Plot 4 | C11: =INDEX('MPDT(star) in EV'!A:A,MATCH(B11,'MPDT(star) in EV'!C:C,0)) -> 1MC06-CEK-EV-FRM-CS04_CL19-000028
A12: HS2-00002WUMK | B12: Whaddon Hill Cutting Planting-West Plot 3 | C12: =INDEX('MPDT(star) in EV'!A:A,MATCH(B12,'MPDT(star) in EV'!C:C,0)) -> 1MC06-CEK-EV-FRM-CS04_CL19-000027
A13: HS2-00002WUMJ | B13: Whaddon Hill Cutting Planting-West Plot 2 | C13: =INDEX('MPDT(star) in EV'!A:A,MATCH(B13,'MPDT(star) in EV'!C:C,0)) -> 1MC06-CEK-EV-FRM-CS04_CL19-000026
... A255: HS2-0000386TG | B255: Mixbury Cutting Planting Plot 1 | C255: =INDEX('MPDT(star) in EV'!A:A,MATCH(B255,'MPDT(star) in EV'!C:C,0)) -> 1MC06-ASC-EV-FRM-CS06_CL22-900001
A256: HS2-00003B93M | B256: Calvert Cutting Planting Plot 17 | C256: =INDEX(MDPTs!A:A,MATCH(B256,MDPTs!C:C,0)) -> 1MC06-ASC-EV-FRM-CS06_CL09-900028
A257: HS2-00003B93L | B257: Calvert Cutting Planting Plot 16 | C257: =INDEX(MDPTs!A:A,MATCH(B257,MDPTs!C:C,0)) -> 1MC06-ASC-EV-FRM-CS06_CL09-900026
A258: HS2-00003B93K | B258: Calvert Cutting Planting Plot 15 | C258: =INDEX(MDPTs!A:A,MATCH(B258,MDPTs!C:C,0)) -> 1MC06-ASC-EV-FRM-CS06_CL09-900025
A259: HS2-00003B93J | B259: Calvert Cutting Planting Plot 14 | C259: =INDEX(MDPTs!A:A,MATCH(B259,MDPTs!C:C,0)) -> 1MC06-ASC-EV-FRM-CS06_CL09-900024
A260: HS2-00003B93H | B260: Calvert Cutting Planting Plot 13 | C260: =INDEX(MDPTs!A:A,MATCH(B260,MDPTs!C:C,0)) -> 1MC06-ASC-EV-FRM-CS06_CL09-900022
A261: HS2-00003B93G | B261: Calvert Cutting Planting Plot 12 | C261: =INDEX(MDPTs!A:A,MATCH(B261,MDPTs!C:C,0)) -> 1MC06-ASC-EV-FRM-CS06_CL09-900020
A262: HS2-00003B93F | B262: Calvert Cutting Planting Plot 11 | C262: =INDEX(MDPTs!A:A,MATCH(B262,MDPTs!C:C,0)) -> 1MC06-ASC-EV-FRM-CS06_CL09-900019
A263: HS2-00003B93D | B263: Calvert Cutting Planting Plot 9 | C263: =INDEX(MDPTs!A:A,MATCH(B263,MDPTs!C:C,0)) -> 1MC06-ASC-EV-FRM-CS06_CL09-900016
A264: HS2-00003B93C | B264: Calvert Cutting Planting Plot 8 | C264: =INDEX(MDPTs!A:A,MATCH(B264,MDPTs!C:C,0)) -> 1MC06-ASC-EV-FRM-CS06_CL09-900014
A265: HS2-00003B93B | B265: Calvert Cutting Planting Plot 7 | C265: =INDEX(MDPTs!A:A,MATCH(B265,MDPTs!C:C,0)) -> 1MC06-ASC-EV-FRM-CS06_CL09-900012
A266: HS2-00003B93A | B266: Calvert Cutting Planting Plot 6 | C266: =INDEX(MDPTs!A:A,MATCH(B266,MDPTs!C:C,0)) -> 1MC06-ASC-EV-FRM-CS06_CL09-900010
A267: HS2-00003B939 | B267: Calvert Cutting Planting Plot 5 | C267: =INDEX(MDPTs!A:A,MATCH(B267,MDPTs!C:C,0)) -> 1MC06-ASC-EV-FRM-CS06_CL09-900008
... A290: HS2-00003B92J | B290: Twyford Embankment planting Plot 1 | C290: =INDEX(MDPTs!A:A,MATCH(B290,MDPTs!C:C,0)) -> 1MC06-ASC-EV-FRM-CS06_CL09-900003
A291: HS2-00003CPYJ | B291: Brackley South Cutting Planting Plot 16 | C291: =INDEX('MPDT(star) in EV'!A:A,MATCH(B291,'MPDT(star) in EV'!C:C,0)) -> 1MC07-ASC-EV-FRM-CS07_CL12-900063
A292: HS2-00003CPYH | B292: Brackley South Cutting Planting Plot 15 | C292: =INDEX('MPDT(star) in EV'!A:A,MATCH(B292,'MPDT(star) in EV'!C:C,0)) -> 1MC07-ASC-EV-FRM-CS07_CL12-900062
A293: HS2-00003CPYF | B293: Brackley South Cutting Planting Plot 14 | C293: =INDEX('MPDT(star) in EV'!A:A,MATCH(B293,'MPDT(star) in EV'!C:C,0)) -> 1MC07-ASC-EV-FRM-CS07_CL12-900061
A294: HS2-00003CPYE | B294: Brackley South Cutting Planting Plot 13 | C294: =INDEX('MPDT(star) in EV'!A:A,MATCH(B294,'MPDT(star) in EV'!C:C,0)) -> 1MC07-ASC-EV-FRM-CS07_CL12-900060
A295: HS2-00003CPYD | B295: Brackley South Cutting Planting Plot 12 | C295: =INDEX('MPDT(star) in EV'!A:A,MATCH(B295,'MPDT(star) in EV'!C:C,0)) -> 1MC07-ASC-EV-FRM-CS07_CL12-900059
A296: HS2-00003CPYC | B296: Brackley South Cutting Planting Plot 11 | C296: =INDEX('MPDT(star) in EV'!A:A,MATCH(B296,'MPDT(star) in EV'!C:C,0)) -> 1MC07-ASC-EV-FRM-CS07_CL12-900058
A297: HS2-00003CPYA | B297: Brackley South Cutting Planting Plot 10 | C297: =INDEX('MPDT(star) in EV'!A:A,MATCH(B297,'MPDT(star) in EV'!C:C,0)) -> 1MC07-ASC-EV-FRM-CS07_CL12-900057
A298: HS2-00003CPY9 | B298: Brackley South Cutting Planting Plot 9 | C298: =INDEX('MPDT(star) in EV'!A:A,MATCH(B298,'MPDT(star) in EV'!C:C,0)) -> 1MC07-ASC-EV-FRM-CS07_CL12-900056
A299: HS2-00003CPY8 | B299: Brackley South Cutting Planting Plot 8 | C299: =INDEX('MPDT(star) in EV'!A:A,MATCH(B299,'MPDT(star) in EV'!C:C,0)) -> 1MC07-ASC-EV-FRM-CS07_CL12-900055
A300: HS2-00003CPY6 | B300: Brackley South Cutting Planting Plot 7 | C300: =INDEX('MPDT(star) in EV'!A:A,MATCH(B300,'MPDT(star) in EV'!C:C,0)) -> 1MC07-ASC-EV-FRM-CS07_CL12-900054
A301: HS2-00003CPY5 | B301: Brackley South Cutting Planting Plot 6 | C301: =INDEX('MPDT(star) in EV'!A:A,MATCH(B301,'MPDT(star) in EV'!C:C,0)) -> 1MC07-ASC-EV-FRM-CS07_CL12-900053
A302: HS2-00003CPY4 | B302: Brackley South Cutting Planting Plot 5 | C302: =INDEX('MPDT(star) in EV'!A:A,MATCH(B302,'MPDT(star) in EV'!C:C,0)) -> 1MC07-ASC-EV-FRM-CS07_CL12-900052
... A344: HS2-00003JYH2 | B344: Greatworth North Embankment Planting-Plot 1 | C344: =INDEX('MPDT(star) in EV'!A:A,MATCH(B344,'MPDT(star) in EV'!C:C,0)) -> 1MC07-ASC-EV-REP-CS07_CL12-000007
...

Sheet MPDT(star) in EV
A1: Name | B1: Description | D1: Rev.Ver | E1: State | F1: Updated By | G1: Updated | H1: File Updated By | I1: File Updated | J1: Created By | K1: Created | L1: File Size | M1: Project ID | N1: Version | O1: Project Title | P1: Folder Name | Q1: Folder Description | R1: Environment | S1: Folder Id | T1: Application | U1: Title | V1: File Name | W1: Out to | X1: File Revision | Y1: Reference Status | Z1: Doc. Reference | AA1: Suitability | AB1: Revision note | AC1: Status
A2: 1MC06-ASC-EV-FRM-CS06_CL09-900035 | B2: MPDT Calvert Cutting Planting Plot 19 | C2: Calvert Cutting Planting Plot 19 | D2: P01 | E2: Approve (Shared) | F2: laurence.meyer_inter.setec.fr | G2: 45608.677 | H2: laurence.meyer_inter.setec.fr | I2: 45608.677 | J2: Hub_DC_Birmingham_Central | K2: 45604.558 | L2: 174 KB | M2: 1MC06 | N2: P01 | O2: North Portal Chiltern Tunnels to Brackley | P2: 01 - Docs | Q2: SDK | R2: HS2_DJV_Documents | S2: 278380 | T2: Microsoft Excel | U2: MPDT Calvert Cutting Planting Plot 19 | V2: 1MC06-ASC-EV-FRM-CS06_CL09-900035.xlsx | Y2: APPROVED | Z2: 1MC06-ASC-EV-FRM-CS06_CL09-900035 | AA2: S3 | AB2: Internal Review | AC2: Final
A3: 1MC06-ASC-EV-FRM-CS06_CL10-900001 | B3: MPDT - Twyford Cutting Planting Plot 1 | C3: Twyford Cutting Planting Plot 1 | D3: P03.1 | E3: Work in Progress | F3: Tamara Georgescu | G3: 46064.772 | H3: laurence.meyer_inter.setec.fr | I3: 45404.6 | J3: Hub_DC_Birmingham_Central | K3: 45167.304 | L3: 182 KB | M3: 1MC06 | N3: P03.1 | O3: North Portal Chiltern Tunnels to Brackley | P3: 01 - Docs | Q3: SDK | R3: HS2_DJV_Documents | S3: 288345 | T3: Microsoft Excel | U3: MPDT - Twyford Cutting Planting Plot 1 | V3: 1MC06-ASC-EV-FRM-CS06_CL10-900001.xlsm | Y3: UNAPPROVED | Z3: 1MC06-ASC-EV-FRM-CS06_CL10-900001 | AA3: S0 | AC3: Checked In
A4: 1MC06-ASC-EV-FRM-CS06_CL10-900001 | B4: MPDT - Twyford Cutting Planting Plot 1 | C4: Twyford Cutting Planting Plot 1 | D4: P02 | E4: Approve (Shared) | F4: Tamara Georgescu | G4: 46064.772 | H4: laurence.meyer_inter.setec.fr | I4: 45404.6 | J4: Tamara Georgescu | K4: 45167.304 | L4: 182 KB | M4: 1MC06 | N4: P02 | O4: North Portal Chiltern Tunnels to Brackley | P4: 01 - Docs | Q4: SDK | R4: HS2_DJV_Documents | S4: 288345 | T4: Microsoft Excel | U4: MPDT - Twyford Cutting Planting Plot 1 | V4: 1MC06-ASC-EV-FRM-CS06_CL10-900001.xlsm | Y4: APPROVED | Z4: 1MC06-ASC-EV-FRM-CS06_CL10-900001 | AA4: S3 | AB4: Revised in line with comments | AC4: Checked In
A5: 1MC06-ASC-EV-FRM-CS06_CL10-900001 | B5: MPDT - Twyford Cutting Planting Plot 1 | C5: Twyford Cutting Planting Plot 1 | D5: P01 | E5: Approve (Shared) | F5: Tamara Georgescu | G5: 45401.368 | H5: laurence.meyer_inter.setec.fr | I5: 45394.659 | J5: Tamara Georgescu | K5: 45167.304 | L5: 182 KB | M5: 1MC06 | N5: P01 | O5: North Portal Chiltern Tunnels to Brackley | P5: 01 - Docs | Q5: SDK | R5: HS2_DJV_Documents | S5: 288345 | T5: Microsoft Excel | U5: MPDT - Twyford Cutting Planting Plot 1 | V5: 1MC06-ASC-EV-FRM-CS06_CL10-900001.xlsm | Y5: APPROVED | Z5: 1MC06-ASC-EV-FRM-CS06_CL10-900001 | AA5: S3 | AB5: First Issue | AC5: Checked In
A6: 1MC06-ASC-EV-FRM-CS06_CL10-900002 | B6: MPDT - Twyford Cutting Planting Plot 2 | C6: Twyford Cutting Planting Plot 2 | D6: P03.1 | E6: Work in Progress | F6: Tamara Georgescu | G6: 46064.772 | H6: laurence.meyer_inter.setec.fr | I6: 45404.601 | J6: Hub_DC_Birmingham_Central | K6: 45167.304 | L6: 184 KB | M6: 1MC06 | N6: P03.1 | O6: North Portal Chiltern Tunnels to Brackley | P6: 01 - Docs | Q6: SDK | R6: HS2_DJV_Documents | S6: 288345 | T6: Microsoft Excel | U6: MPDT - Twyford Cutting Planting Plot 2 | V6: 1MC06-ASC-EV-FRM-CS06_CL10-900002.xlsm | Y6: UNAPPROVED | Z6: 1MC06-ASC-EV-FRM-CS06_CL10-900002 | AA6: S0 | AC6: Checked In
A7: 1MC06-ASC-EV-FRM-CS06_CL10-900002 | B7: MPDT - Twyford Cutting Planting Plot 2 | C7: Twyford Cutting Planting Plot 2 | D7: P02 | E7: Approve (Shared) | F7: Tamara Georgescu | G7: 46064.772 | H7: laurence.meyer_inter.setec.fr | I7: 45404.601 | J7: Tamara Georgescu | K7: 45167.304 | L7: 184 KB | M7: 1MC06 | N7: P02 | O7: North Portal Chiltern Tunnels to Brackley | P7: 01 - Docs | Q7: SDK | R7: HS2_DJV_Documents | S7: 288345 | T7: Microsoft Excel | U7: MPDT - Twyford Cutting Planting Plot 2 | V7: 1MC06-ASC-EV-FRM-CS06_CL10-900002.xlsm | Y7: APPROVED | Z7: 1MC06-ASC-EV-FRM-CS06_CL10-900002 | AA7: S3 | AB7: Revised in line with comments | AC7: Checked In
A8: 1MC06-ASC-EV-FRM-CS06_CL10-900002 | B8: MPDT - Twyford Cutting Planting Plot 2 | C8: Twyford Cutting Planting Plot 2 | D8: P01 | E8: Approve (Shared) | F8: Tamara Georgescu | G8: 45401.368 | H8: laurence.meyer_inter.setec.fr | I8: 45394.659 | J8: Tamara Georgescu | K8: 45167.304 | L8: 184 KB | M8: 1MC06 | N8: P01 | O8: North Portal Chiltern Tunnels to Brackley | P8: 01 - Docs | Q8: SDK | R8: HS2_DJV_Documents | S8: 288345 | T8: Microsoft Excel | U8: MPDT - Twyford Cutting Planting Plot 2 | V8: 1MC06-ASC-EV-FRM-CS06_CL10-900002.xlsm | Y8: APPROVED | Z8: 1MC06-ASC-EV-FRM-CS06_CL10-900002 | AA8: S3 | AB8: First Issue | AC8: Checked In
A9: 1MC06-ASC-EV-FRM-CS06_CL10-900003 | B9: MPDT - Twyford Cutting Planting Plot 3 | C9: Twyford Cutting Planting Plot 3 | D9: P03.1 | E9: Work in Progress | F9: Tamara Georgescu | G9: 46064.772 | H9: laurence.meyer_inter.setec.fr | I9: 45404.601 | J9: Hub_DC_Birmingham_Central | K9: 45167.304 | L9: 180 KB | M9: 1MC06 | N9: P03.1 | O9: North Portal Chiltern Tunnels to Brackley | P9: 01 - Docs | Q9: SDK | R9: HS2_DJV_Documents | S9: 288345 | T9: Microsoft Excel | U9: MPDT - Twyford Cutting Planting Plot 3 | V9: 1MC06-ASC-EV-FRM-CS06_CL10-900003.xlsm | Y9: UNAPPROVED | Z9: 1MC06-ASC-EV-FRM-CS06_CL10-900003 | AA9: S0 | AC9: Checked In
A10: 1MC06-ASC-EV-FRM-CS06_CL10-900003 | B10: MPDT - Twyford Cutting Planting Plot 3 | C10: Twyford Cutting Planting Plot 3 | D10: P02 | E10: Approve (Shared) | F10: Tamara Georgescu | G10: 46064.772 | H10: laurence.meyer_inter.setec.fr | I10: 45404.601 | J10: Tamara Georgescu | K10: 45167.304 | L10: 180 KB | M10: 1MC06 | N10: P02 | O10: North Portal Chiltern Tunnels to Brackley | P10: 01 - Docs | Q10: SDK | R10: HS2_DJV_Documents | S10: 288345 | T10: Microsoft Excel | U10: MPDT - Twyford Cutting Planting Plot 3 | V10: 1MC06-ASC-EV-FRM-CS06_CL10-900003.xlsm | Y10: APPROVED | Z10: 1MC06-ASC-EV-FRM-CS06_CL10-900003 | AA10: S3 | AB10: Revised in line with comments | AC10: Checked In
A11: 1MC06-ASC-EV-FRM-CS06_CL10-900003 | B11: MPDT - Twyford Cutting Planting Plot 3 | C11: Twyford Cutting Planting Plot 3 | D11: P01 | E11: Approve (Shared) | F11: Tamara Georgescu | G11: 45401.368 | H11: laurence.meyer_inter.setec.fr | I11: 45394.659 | J11: Tamara Georgescu | K11: 45167.304 | L11: 180 KB | M11: 1MC06 | N11: P01 | O11: North Portal Chiltern Tunnels to Brackley | P11: 01 - Docs | Q11: SDK | R11: HS2_DJV_Documents | S11: 288345 | T11: Microsoft Excel | U11: MPDT - Twyford Cutting Planting Plot 3 | V11: 1MC06-ASC-EV-FRM-CS06_CL10-900003.xlsm | Y11: APPROVED | Z11: 1MC06-ASC-EV-FRM-CS06_CL10-900003 | AA11: S3 | AB11: First Issue | AC11: Checked In
A12: 1MC06-ASC-EV-FRM-CS06_CL10-900004 | B12: MPDT - Twyford Cutting Planting Plot 4 | C12: Twyford Cutting Planting Plot 4 | D12: P03.1 | E12: Work in Progress | F12: Tamara Georgescu | G12: 46064.772 | H12: laurence.meyer_inter.setec.fr | I12: 45404.601 | J12: Hub_DC_Birmingham_Central | K12: 45167.304 | L12: 186 KB | M12: 1MC06 | N12: P03.1 | O12: North Portal Chiltern Tunnels to Brackley | P12: 01 - Docs | Q12: SDK | R12: HS2_DJV_Documents | S12: 288345 | T12: Microsoft Excel | U12: MPDT - Twyford Cutting Planting Plot 4 | V12: 1MC06-ASC-EV-FRM-CS06_CL10-900004.xlsm | Y12: UNAPPROVED | Z12: 1MC06-ASC-EV-FRM-CS06_CL10-900004 | AA12: S0 | AC12: Checked In
A13: 1MC06-ASC-EV-FRM-CS06_CL10-900004 | B13: MPDT - Twyford Cutting Planting Plot 4 | C13: Twyford Cutting Planting Plot 4 | D13: P02 | E13: Approve (Shared) | F13: Tamara Georgescu | G13: 46064.772 | H13: laurence.meyer_inter.setec.fr | I13: 45404.601 | J13: Tamara Georgescu | K13: 45167.304 | L13: 186 KB | M13: 1MC06 | N13: P02 | O13: North Portal Chiltern Tunnels to Brackley | P13: 01 - Docs | Q13: SDK | R13: HS2_DJV_Documents | S13: 288345 | T13: Microsoft Excel | U13: MPDT - Twyford Cutting Planting Plot 4 | V13: 1MC06-ASC-EV-FRM-CS06_CL10-900004.xlsm | Y13: APPROVED | Z13: 1MC06-ASC-EV-FRM-CS06_CL10-900004 | AA13: S3 | AB13: Revised in line with comments | AC13: Checked In
A14: 1MC06-ASC-EV-FRM-CS06_CL10-900004 | B14: MPDT - Twyford Cutting Planting Plot 4 | C14: Twyford Cutting Planting Plot 4 | D14: P01 | E14: Approve (Shared) | F14: Tamara Georgescu | G14: 45401.368 | H14: guillaume.grandamy_setec.com | I14: 45396.968 | J14: Tamara Georgescu | K14: 45167.304 | L14: 186 KB | M14: 1MC06 | N14: P01 | O14: North Portal Chiltern Tunnels to Brackley | P14: 01 - Docs | Q14: SDK | R14: HS2_DJV_Documents | S14: 288345 | T14: Microsoft Excel | U14: MPDT - Twyford Cutting Planting Plot 4 | V14: 1MC06-ASC-EV-FRM-CS06_CL10-900004.xlsm | Y14: APPROVED | Z14: 1MC06-ASC-EV-FRM-CS06_CL10-900004 | AA14: S3 | AB14: First Issue | AC14: Checked In
A15: 1MC06-ASC-EV-FRM-CS06_CL10-900005 | B15: MPDT - Twyford Cutting Planting Plot 5 | C15: Twyford Cutting Planting Plot 5 | D15: P03.1 | E15: Work in Progress | F15: Tamara Georgescu | G15: 46064.772 | H15: laurence.meyer_inter.setec.fr | I15: 45404.601 | J15: Hub_DC_Birmingham_Central | K15: 45167.304 | L15: 180 KB | M15: 1MC06 | N15: P03.1 | O15: North Portal Chiltern Tunnels to Brackley | P15: 01 - Docs | Q15: SDK | R15: HS2_DJV_Documents | S15: 288345 | T15: Microsoft Excel | U15: MPDT - Twyford Cutting Planting Plot 5 | V15: 1MC06-ASC-EV-FRM-CS06_CL10-900005.xlsm | Y15: UNAPPROVED | Z15: 1MC06-ASC-EV-FRM-CS06_CL10-900005 | AA15: S0 | AC15: Checked In
A16: 1MC06-ASC-EV-FRM-CS06_CL10-900005 | B16: MPDT - Twyford Cutting Planting Plot 5 | C16: Twyford Cutting Planting Plot 5 | D16: P02 | E16: Approve (Shared) | F16: Tamara Georgescu | G16: 46064.772 | H16: laurence.meyer_inter.setec.fr | I16: 45404.601 | J16: Tamara Georgescu | K16: 45167.304 | L16: 180 KB | M16: 1MC06 | N16: P02 | O16: North Portal Chiltern Tunnels to Brackley | P16: 01 - Docs | Q16: SDK | R16: HS2_DJV_Documents | S16: 288345 | T16: Microsoft Excel | U16: MPDT - Twyford Cutting Planting Plot 5 | V16: 1MC06-ASC-EV-FRM-CS06_CL10-900005.xlsm | Y16: APPROVED | Z16: 1MC06-ASC-EV-FRM-CS06_CL10-900005 | AA16: S3 | AB16: Revised in line with comments | AC16: Checked In
A17: 1MC06-ASC-EV-FRM-CS06_CL10-900005 | B17: MPDT - Twyford Cutting Planting Plot 5 | C17: Twyford Cutting Planting Plot 5 | D17: P01 | E17: Approve (Shared) | F17: Tamara Georgescu | G17: 45401.368 | H17: guillaume.grandamy_setec.com | I17: 45396.969 | J17: Tamara Georgescu | K17: 45167.304 | L17: 180 KB | M17: 1MC06 | N17: P01 | O17: North Portal Chiltern Tunnels to Brackley | P17: 01 - Docs | Q17: SDK | R17: HS2_DJV_Documents | S17: 288345 | T17: Microsoft Excel | U17: MPDT - Twyford Cutting Planting Plot 5 | V17: 1MC06-ASC-EV-FRM-CS06_CL10-900005.xlsm | Y17: APPROVED | Z17: 1MC06-ASC-EV-FRM-CS06_CL10-900005 | AA17: S3 | AB17: First Issue | AC17: Checked In
A18: 1MC06-ASC-EV-FRM-CS06_CL10-900006 | B18: MPDT - Twyford Cutting Planting Plot 6 | C18: Twyford Cutting Planting Plot 6 | D18: P03.1 | E18: Work in Progress | F18: Tamara Georgescu | G18: 46064.772 | H18: laurence.meyer_inter.setec.fr | I18: 45404.601 | J18: Hub_DC_Birmingham_Central | K18: 45167.304 | L18: 186 KB | M18: 1MC06 | N18: P03.1 | O18: North Portal Chiltern Tunnels to Brackley | P18: 01 - Docs | Q18: SDK | R18: HS2_DJV_Documents | S18: 288345 | T18: Microsoft Excel | U18: MPDT - Twyford Cutting Planting Plot 6 | V18: 1MC06-ASC-EV-FRM-CS06_CL10-900006.xlsm | Y18: UNAPPROVED | Z18: 1MC06-ASC-EV-FRM-CS06_CL10-900006 | AA18: S0 | AC18: Checked In
A19: 1MC06-ASC-EV-FRM-CS06_CL10-900006 | B19: MPDT - Twyford Cutting Planting Plot 6 | C19: Twyford Cutting Planting Plot 6 | D19: P02 | E19: Approve (Shared) | F19: Tamara Georgescu | G19: 46064.772 | H19: laurence.meyer_inter.setec.fr | I19: 45404.601 | J19: Tamara Georgescu | K19: 45167.304 | L19: 186 KB | M19: 1MC06 | N19: P02 | O19: North Portal Chiltern Tunnels to Brackley | P19: 01 - Docs | Q19: SDK | R19: HS2_DJV_Documents | S19: 288345 | T19: Microsoft Excel | U19: MPDT - Twyford Cutting Planting Plot 6 | V19: 1MC06-ASC-EV-FRM-CS06_CL10-900006.xlsm | Y19: APPROVED | Z19: 1MC06-ASC-EV-FRM-CS06_CL10-900006 | AA19: S3 | AB19: Revised in line with comments | AC19: Checked In
A20: 1MC06-ASC-EV-FRM-CS06_CL10-900006 | B20: MPDT - Twyford Cutting Planting Plot 6 | C20: Twyford Cutting Planting Plot 6 | D20: P01 | E20: Approve (Shared) | F20: Tamara Georgescu | G20: 45401.368 | H20: guillaume.grandamy_setec.com | I20: 45396.969 | J20: Tamara Georgescu | K20: 45167.304 | L20: 186 KB | M20: 1MC06 | N20: P01 | O20: North Portal Chiltern Tunnels to Brackley | P20: 01 - Docs | Q20: SDK | R20: HS2_DJV_Documents | S20: 288345 | T20: Microsoft Excel | U20: MPDT - Twyford Cutting Planting Plot 6 | V20: 1MC06-ASC-EV-FRM-CS06_CL10-900006.xlsm | Y20: APPROVED | Z20: 1MC06-ASC-EV-FRM-CS06_CL10-900006 | AA20: S3 | AB20: First Issue | AC20: Checked In
A21: 1MC06-ASC-EV-FRM-CS06_CL10-900007 | B21: MPDT - Twyford Cutting Planting Plot 7 | C21: Twyford Cutting Planting Plot 7 | D21: P03.1 | E21: Work in Progress | F21: Tamara Georgescu | G21: 46064.772 | H21: laurence.meyer_inter.setec.fr | I21: 45404.601 | J21: Hub_DC_Birmingham_Central | K21: 45167.304 | L21: 183 KB | M21: 1MC06 | N21: P03.1 | O21: North Portal Chiltern Tunnels to Brackley | P21: 01 - Docs | Q21: SDK | R21: HS2_DJV_Documents | S21: 288345 | T21: Microsoft Excel | U21: MPDT - Twyford Cutting Planting Plot 7 | V21: 1MC06-ASC-EV-FRM-CS06_CL10-900007.xlsm | Y21: UNAPPROVED | Z21: 1MC06-ASC-EV-FRM-CS06_CL10-900007 | AA21: S0 | AC21: Checked In
A22: 1MC06-ASC-EV-FRM-CS06_CL10-900007 | B22: MPDT - Twyford Cutting Planting Plot 7 | C22: Twyford Cutting Planting Plot 7 | D22: P02 | E22: Approve (Shared) | F22: Tamara Georgescu | G22: 46064.772 | H22: laurence.meyer_inter.setec.fr | I22: 45404.601 | J22: Tamara Georgescu | K22: 45167.304 | L22: 183 KB | M22: 1MC06 | N22: P02 | O22: North Portal Chiltern Tunnels to Brackley | P22: 01 - Docs | Q22: SDK | R22: HS2_DJV_Documents | S22: 288345 | T22: Microsoft Excel | U22: MPDT - Twyford Cutting Planting Plot 7 | V22: 1MC06-ASC-EV-FRM-CS06_CL10-900007.xlsm | Y22: APPROVED | Z22: 1MC06-ASC-EV-FRM-CS06_CL10-900007 | AA22: S3 | AB22: Revised in line with comments | AC22: Checked In
A23: 1MC06-ASC-EV-FRM-CS06_CL10-900007 | B23: MPDT - Twyford Cutting Planting Plot 7 | C23: Twyford Cutting Planting Plot 7 | D23: P01 | E23: Approve (Shared) | F23: Tamara Georgescu | G23: 45401.369 | H23: laurence.meyer_inter.setec.fr | I23: 45394.659 | J23: Tamara Georgescu | K23: 45167.304 | L23: 184 KB | M23: 1MC06 | N23: P01 | O23: North Portal Chiltern Tunnels to Brackley | P23: 01 - Docs | Q23: SDK | R23: HS2_DJV_Documents | S23: 288345 | T23: Microsoft Excel | U23: MPDT - Twyford Cutting Planting Plot 7 | V23: 1MC06-ASC-EV-FRM-CS06_CL10-900007.xlsm | Y23: APPROVED | Z23: 1MC06-ASC-EV-FRM-CS06_CL10-900007 | AA23: S3 | AB23: First Issue | AC23: Checked In
A24: 1MC06-ASC-EV-FRM-CS06_CL10-900008 | B24: MPDT - Twyford Cutting Planting Plot 8 | C24: Twyford Cutting Planting Plot 8 | D24: P03.1 | E24: Work in Progress | F24: Tamara Georgescu | G24: 46064.772 | H24: laurence.meyer_inter.setec.fr | I24: 45404.601 | J24: Hub_DC_Birmingham_Central | K24: 45167.304 | L24: 189 KB | M24: 1MC06 | N24: P03.1 | O24: North Portal Chiltern Tunnels to Brackley | P24: 01 - Docs | Q24: SDK | R24: HS2_DJV_Documents | S24: 288345 | T24: Microsoft Excel | U24: MPDT - Twyford Cutting Planting Plot 8 | V24: 1MC06-ASC-EV-FRM-CS06_CL10-900008.xlsm | Y24: UNAPPROVED | Z24: 1MC06-ASC-EV-FRM-CS06_CL10-900008 | AA24: S0 | AC24: Checked In
A25: 1MC06-ASC-EV-FRM-CS06_CL10-900008 | B25: MPDT - Twyford Cutting Planting Plot 8 | C25: Twyford Cutting Planting Plot 8 | D25: P02 | E25: Approve (Shared) | F25: Tamara Georgescu | G25: 46064.772 | H25: laurence.meyer_inter.setec.fr | I25: 45404.601 | J25: Tamara Georgescu | K25: 45167.304 | L25: 189 KB | M25: 1MC06 | N25: P02 | O25: North Portal Chiltern Tunnels to Brackley | P25: 01 - Docs | Q25: SDK | R25: HS2_DJV_Documents | S25: 288345 | T25: Microsoft Excel | U25: MPDT - Twyford Cutting Planting Plot 8 | V25: 1MC06-ASC-EV-FRM-CS06_CL10-900008.xlsm | Y25: APPROVED | Z25: 1MC06-ASC-EV-FRM-CS06_CL10-900008 | AA25: S3 | AB25: Revised in line with comments | AC25: Checked In
A26: 1MC06-ASC-EV-FRM-CS06_CL10-900008 | B26: MPDT - Twyford Cutting Planting Plot 8 | C26: Twyford Cutting Planting Plot 8 | D26: P01 | E26: Approve (Shared) | F26: Tamara Georgescu | G26: 45401.369 | H26: laurence.meyer_inter.setec.fr | I26: 45394.659 | J26: Tamara Georgescu | K26: 45167.304 | L26: 189 KB | M26: 1MC06 | N26: P01 | O26: North Portal Chiltern Tunnels to Brackley | P26: 01 - Docs | Q26: SDK | R26: HS2_DJV_Documents | S26: 288345 | T26: Microsoft Excel | U26: MPDT - Twyford Cutting Planting Plot 8 | V26: 1MC06-ASC-EV-FRM-CS06_CL10-900008.xlsm | Y26: APPROVED | Z26: 1MC06-ASC-EV-FRM-CS06_CL10-900008 | AA26: S3 | AB26: First Issue | AC26: Checked In
A27: 1MC06-ASC-EV-FRM-CS06_CL10-900009 | B27: MPDT - Twyford Viaduct Planting Plot 1 | C27: Twyford Viaduct Planting Plot 1 | D27: P03.1 | E27: Work in Progress | F27: Tamara Georgescu | G27: 46064.773 | H27: laurence.meyer_inter.setec.fr | I27: 45404.601 | J27: Hub_DC_Birmingham_Central | K27: 45168.48 | L27: 169 KB | M27: 1MC06 | N27: P03.1 | O27: North Portal Chiltern Tunnels to Brackley | P27: 01 - Docs | Q27: SDK | R27: HS2_DJV_Documents | S27: 289364 | T27: Microsoft Excel | U27: MPDT - Twyford Viaduct Planting Plot 1 | V27: 1MC06-ASC-EV-FRM-CS06_CL10-900009.xlsm | Y27: UNAPPROVED | Z27: 1MC06-ASC-EV-FRM-CS06_CL10-900009 | AA27: S0 | AC27: Checked In
A28: 1MC06-ASC-EV-FRM-CS06_CL10-900009 | B28: MPDT - Twyford Viaduct Planting Plot 1 | C28: Twyford Viaduct Planting Plot 1 | D28: P02 | E28: Approve (Shared) | F28: Tamara Georgescu | G28: 46064.773 | H28: laurence.meyer_inter.setec.fr | I28: 45404.601 | J28: Tamara Georgescu | K28: 45168.48 | L28: 169 KB | M28: 1MC06 | N28: P02 | O28: North Portal Chiltern Tunnels to Brackley | P28: 01 - Docs | Q28: SDK | R28: HS2_DJV_Documents | S28: 289364 | T28: Microsoft Excel | U28: MPDT - Twyford Viaduct Planting Plot 1 | V28: 1MC06-ASC-EV-FRM-CS06_CL10-900009.xlsm | Y28: APPROVED | Z28: 1MC06-ASC-EV-FRM-CS06_CL10-900009 | AA28: S3 | AB28: Revised in line with comments | AC28: Checked In
A29: 1MC06-ASC-EV-FRM-CS06_CL10-900009 | B29: MPDT - Twyford Viaduct Planting Plot 1 | C29: Twyford Viaduct Planting Plot 1 | D29: P01 | E29: Approve (Shared) | F29: Tamara Georgescu | G29: 45401.623 | H29: laurence.meyer_inter.setec.fr | I29: 45394.652 | J29: Tamara Georgescu | K29: 45168.48 | L29: 169 KB | M29: 1MC06 | N29: P01 | O29: North Portal Chiltern Tunnels to Brackley | P29: 01 - Docs | Q29: SDK | R29: HS2_DJV_Documents | S29: 289364 | T29: Microsoft Excel | U29: MPDT - Twyford Viaduct Planting Plot 1 | V29: 1MC06-ASC-EV-FRM-CS06_CL10-900009.xlsm | Y29: APPROVED | Z29: 1MC06-ASC-EV-FRM-CS06_CL10-900009 | AA29: S3 | AB29: First Issue | AC29: Checked In
A30: 1MC06-ASC-EV-FRM-CS06_CL10-900010 | B30: MPDT - Twyford Viaduct Planting Plot 2 | C30: Twyford Viaduct Planting Plot 2 | D30: P03.1 | E30: Work in Progress | F30: Tamara Georgescu | G30: 46064.773 | H30: laurence.meyer_inter.setec.fr | I30: 45404.602 | J30: Hub_DC_Birmingham_Central | K30: 45168.48 | L30: 171 KB | M30: 1MC06 | N30: P03.1 | O30: North Portal Chiltern Tunnels to Brackley | P30: 01 - Docs | Q30: SDK | R30: HS2_DJV_Documents | S30: 289364 | T30: Microsoft Excel | U30: MPDT - Twyford Viaduct Planting Plot 2 | V30: 1MC06-ASC-EV-FRM-CS06_CL10-900010.xlsm | Y30: UNAPPROVED | Z30: 1MC06-ASC-EV-FRM-CS06_CL10-900010 | AA30: S0 | AC30: Checked In
A31: 1MC06-ASC-EV-FRM-CS06_CL10-900010 | B31: MPDT - Twyford Viaduct Planting Plot 2 | C31: Twyford Viaduct Planting Plot 2 | D31: P02 | E31: Approve (Shared) | F31: Tamara Georgescu | G31: 46064.773 | H31: laurence.meyer_inter.setec.fr | I31: 45404.602 | J31: Tamara Georgescu | K31: 45168.48 | L31: 171 KB | M31: 1MC06 | N31: P02 | O31: North Portal Chiltern Tunnels to Brackley | P31: 01 - Docs | Q31: SDK | R31: HS2_DJV_Documents | S31: 289364 | T31: Microsoft Excel | U31: MPDT - Twyford Viaduct Planting Plot 2 | V31: 1MC06-ASC-EV-FRM-CS06_CL10-900010.xlsm | Y31: APPROVED | Z31: 1MC06-ASC-EV-FRM-CS06_CL10-900010 | AA31: S3 | AB31: Revised in line with comments | AC31: Checked In
A32: 1MC06-ASC-EV-FRM-CS06_CL10-900010 | B32: MPDT - Twyford Viaduct Planting Plot 2 | C32: Twyford Viaduct Planting Plot 2 | D32: P01 | E32: Approve (Shared) | F32: Tamara Georgescu | G32: 45401.623 | H32: laurence.meyer_inter.setec.fr | I32: 45394.651 | J32: Tamara Georgescu | K32: 45168.48 | L32: 171 KB | M32: 1MC06 | N32: P01 | O32: North Portal Chiltern Tunnels to Brackley | P32: 01 - Docs | Q32: SDK | R32: HS2_DJV_Documents | S32: 289364 | T32: Microsoft Excel | U32: MPDT - Twyford Viaduct Planting Plot 2 | V32: 1MC06-ASC-EV-FRM-CS06_CL10-900010.xlsm | Y32: APPROVED | Z32: 1MC06-ASC-EV-FRM-CS06_CL10-900010 | AA32: S3 | AB32: First Issue | AC32: Checked In
A33: 1MC06-ASC-EV-FRM-CS06_CL10-900011 | B33: MPDT - Twyford Viaduct Planting Plot 3 | C33: Twyford Viaduct Planting Plot 3 | D33: P03.1 | E33: Work in Progress | F33: Tamara Georgescu | G33: 46064.773 | H33: laurence.meyer_inter.setec.fr | I33: 45404.602 | J33: Hub_DC_Birmingham_Central | K33: 45168.48 | L33: 174 KB | M33: 1MC06 | N33: P03.1 | O33: North Portal Chiltern Tunnels to Brackley | P33: 01 - Docs | Q33: SDK | R33: HS2_DJV_Documents | S33: 289364 | T33: Microsoft Excel | U33: MPDT - Twyford Viaduct Planting Plot 3 | V33: 1MC06-ASC-EV-FRM-CS06_CL10-900011.xlsm | Y33: UNAPPROVED | Z33: 1MC06-ASC-EV-FRM-CS06_CL10-900011 | AA33: S0 | AC33: Checked In
A34: 1MC06-ASC-EV-FRM-CS06_CL10-900011 | B34: MPDT - Twyford Viaduct Planting Plot 3 | C34: Twyford Viaduct Planting Plot 3 | D34: P02 | E34: Approve (Shared) | F34: Tamara Georgescu | G34: 46064.773 | H34: laurence.meyer_inter.setec.fr | I34: 45404.602 | J34: Tamara Georgescu | K34: 45168.48 | L34: 174 KB | M34: 1MC06 | N34: P02 | O34: North Portal Chiltern Tunnels to Brackley | P34: 01 - Docs | Q34: SDK | R34: HS2_DJV_Documents | S34: 289364 | T34: Microsoft Excel | U34: MPDT - Twyford Viaduct Planting Plot 3 | V34: 1MC06-ASC-EV-FRM-CS06_CL10-900011.xlsm | Y34: APPROVED | Z34: 1MC06-ASC-EV-FRM-CS06_CL10-900011 | AA34: S3 | AB34: Revised in line with comments | AC34: Checked In
A35: 1MC06-ASC-EV-FRM-CS06_CL10-900011 | B35: MPDT - Twyford Viaduct Planting Plot 3 | C35: Twyford Viaduct Planting Plot 3 | D35: P01 | E35: Approve (Shared) | F35: Tamara Georgescu | G35: 45401.623 | H35: laurence.meyer_inter.setec.fr | I35: 45394.651 | J35: Tamara Georgescu | K35: 45168.48 | L35: 174 KB | M35: 1MC06 | N35: P01 | O35: North Portal Chiltern Tunnels to Brackley | P35: 01 - Docs | Q35: SDK | R35: HS2_DJV_Documents | S35: 289364 | T35: Microsoft Excel | U35: MPDT - Twyford Viaduct Planting Plot 3 | V35: 1MC06-ASC-EV-FRM-CS06_CL10-900011.xlsm | Y35: APPROVED | Z35: 1MC06-ASC-EV-FRM-CS06_CL10-900011 | AA35: S3 | AB35: First Issue | AC35: Checked In
A36: 1MC06-ASC-EV-FRM-CS06_CL10-900012 | B36: MPDT - Twyford Viaduct Planting Plot 4 | C36: Twyford Viaduct Planting Plot 4 | D36: P03.1 | E36: Work in Progress | F36: Tamara Georgescu | G36: 46064.774 | H36: laurence.meyer_inter.setec.fr | I36: 45404.599 | J36: Hub_DC_Birmingham_Central | K36: 45168.48 | L36: 170 KB | M36: 1MC06 | N36: P03.1 | O36: North Portal Chiltern Tunnels to Brackley | P36: 01 - Docs | Q36: SDK | R36: HS2_DJV_Documents | S36: 289364 | T36: Microsoft Excel | U36: MPDT - Twyford Viaduct Planting Plot 4 | V36: 1MC06-ASC-EV-FRM-CS06_CL10-900012.xlsm | Y36: UNAPPROVED | Z36: 1MC06-ASC-EV-FRM-CS06_CL10-900012 | AA36: S0 | AC36: Checked In
A37: 1MC06-ASC-EV-FRM-CS06_CL10-900012 | B37: MPDT - Twyford Viaduct Planting Plot 4 | C37: Twyford Viaduct Planting Plot 4 | D37: P02 | E37: Approve (Shared) | F37: Tamara Georgescu | G37: 46064.773 | H37: laurence.meyer_inter.setec.fr | I37: 45404.599 | J37: Tamara Georgescu | K37: 45168.48 | L37: 170 KB | M37: 1MC06 | N37: P02 | O37: North Portal Chiltern Tunnels to Brackley | P37: 01 - Docs | Q37: SDK | R37: HS2_DJV_Documents | S37: 289364 | T37: Microsoft Excel | U37: MPDT - Twyford Viaduct Planting Plot 4 | V37: 1MC06-ASC-EV-FRM-CS06_CL10-900012.xlsm | Y37: APPROVED | Z37: 1MC06-ASC-EV-FRM-CS06_CL10-900012 | AA37: S3 | AB37: Revised in line with comments | AC37: Checked In
A38: 1MC06-ASC-EV-FRM-CS06_CL10-900012 | B38: MPDT - Twyford Viaduct Planting Plot 4 | C38: Twyford Viaduct Planting Plot 4 | D38: P01 | E38: Approve (Shared) | F38: Tamara Georgescu | G38: 45401.624 | H38: laurence.meyer_inter.setec.fr | I38: 45394.651 | J38: Tamara Georgescu | K38: 45168.48 | L38: 170 KB | M38: 1MC06 | N38: P01 | O38: North Portal Chiltern Tunnels to Brackley | P38: 01 - Docs | Q38: SDK | R38: HS2_DJV_Documents | S38: 289364 | T38: Microsoft Excel | U38: MPDT - Twyford Viaduct Planting Plot 4 | V38: 1MC06-ASC-EV-FRM-CS06_CL10-900012.xlsm | Y38: APPROVED | Z38: 1MC06-ASC-EV-FRM-CS06_CL10-900012 | AA38: S3 | AB38: First Issue | AC38: Checked In
A39: 1MC06-ASC-EV-FRM-CS06_CL10-900013 | B39: MPDT - Cowley Embankment Planting Plot 1 | C39: Cowley Embankment Planting Plot 1 | D39: P03.1 | E39: Work in Progress | F39: Tamara Georgescu | G39: 46064.771 | H39: laurence.meyer_inter.setec.fr | I39: 45404.602 | J39: Hub_DC_Birmingham_Central | K39: 45168.48 | L39: 188 KB | M39: 1MC06 | N39: P03.1 | O39: North Portal Chiltern Tunnels to Brackley | P39: 01 - Docs | Q39: SDK | R39: HS2_DJV_Documents | S39: 311433 | T39: Microsoft Excel | U39: MPDT - Cowley Embankment Planting Plot 1 | V39: 1MC06-ASC-EV-FRM-CS06_CL10-900013.xlsm | Y39: UNAPPROVED | Z39: 1MC06-ASC-EV-FRM-CS06_CL10-900013 | AA39: S0 | AC39: Checked In
A40: 1MC06-ASC-EV-FRM-CS06_CL10-900013 | B40: MPDT - Cowley Embankment Planting Plot 1 | C40: Cowley Embankment Planting Plot 1 | D40: P02 | E40: Approve (Shared) | F40: Tamara Georgescu | G40: 46064.771 | H40: laurence.meyer_inter.setec.fr | I40: 45404.602 | J40: Tamara Georgescu | K40: 45168.48 | L40: 188 KB | M40: 1MC06 | N40: P02 | O40: North Portal Chiltern Tunnels to Brackley | P40: 01 - Docs | Q40: SDK | R40: HS2_DJV_Documents | S40: 311433 | T40: Microsoft Excel | U40: MPDT - Cowley Embankment Planting Plot 1 | V40: 1MC06-ASC-EV-FRM-CS06_CL10-900013.xlsm | Y40: APPROVED | Z40: 1MC06-ASC-EV-FRM-CS06_CL10-900013 | AA40: S3 | AB40: Revised in line with comments | AC40: Checked In
...

Sheet (star)MPDT in EV
A1: Name | B1: Description | D1: Rev.Ver | E1: State | F1: Updated By | G1: Updated | H1: File Updated By | I1: File Updated | J1: Created By | K1: Created | L1: File Size | M1: Project ID | N1: Version | O1: Project Title | P1: Folder Name | Q1: Folder Description | R1: Environment | S1: Folder Id | T1: Application | U1: Title | V1: File Name | W1: Out to | X1: File Revision | Y1: Reference Status | Z1: Doc. Reference | AA1: Suitability | AB1: Revision note | AC1: Status
A2: 1MC06-CEK-EV-FRM-CS03_CL05-000002 | B2: NOT USED - Rocky Lane Cutting Landscape Planting - MPDT | C2: Rocky Lane Cutting Landscape Planting | D2: P01.1 | E2: Work in Progress | F2: Alexander Granados-Potts | G2: 45634.71 | H2: Hub_DC_Birmingham_Central | I2: 44995.593 | J2: Hub_DC_Birmingham_Central | K2: 44995.593 | L2: 58 KB | M2: 1MC06 | N2: P01.1 | O2: North Portal Chiltern Tunnels to Brackley | P2: 01 - Docs | Q2: SDK | R2: HS2_DJV_Documents | S2: 284879 | T2: Microsoft Excel | U2: Rocky Lane Cutting Landscape Planting - MPDT | V2: 1MC06-CEK-EV-FRM-CS03_CL05-000002.xlsx | Z2: 1MC06-CEK-EV-FRM-CS03_CL05-000002 | AA2: S0 | AB2: Internal review | AC2: Final
A3: 1MC06-CEK-EV-FRM-CS03_CL05-000003 | B3: Small Dean South Embankment Landscape Planting - MPDT | C3: Small Dean South Embankment Landscape Planting | D3: P01.1 | E3: Work in Progress | F3: Alexander Granados-Potts | G3: 45634.71 | H3: Hub_DC_Birmingham_Central | I3: 44995.593 | J3: Hub_DC_Birmingham_Central | K3: 44995.593 | L3: 58 KB | M3: 1MC06 | N3: P01.1 | O3: North Portal Chiltern Tunnels to Brackley | P3: 01 - Docs | Q3: SDK | R3: HS2_DJV_Documents | S3: 285097 | T3: Microsoft Excel | U3: Small Dean South Embankment Landscape Planting - MPDT | V3: 1MC06-CEK-EV-FRM-CS03_CL05-000003.xlsx | Z3: 1MC06-CEK-EV-FRM-CS03_CL05-000003 | AA3: S0 | AB3: Internal review | AC3: Final
A4: 1MC06-CEK-EV-FRM-CS03_CL05-000004 | B4: South Heath Cutting Landscape Planting - MPDT | C4: South Heath Cutting Landscape Planting | D4: P01.1 | E4: Unassigned | F4: Alexander Granados-Potts | G4: 45634.71 | H4: Hub_DC_Birmingham_Central | I4: 44995.593 | J4: Hub_DC_Birmingham_Central | K4: 44995.593 | L4: 58 KB | M4: 1MC06 | N4: P01.1 | O4: North Portal Chiltern Tunnels to Brackley | P4: 01 - Docs | Q4: SDK | R4: HS2_DJV_Documents | S4: 286097 | T4: Microsoft Excel | U4: South Heath Cutting Landscape Planting - MPDT | V4: 1MC06-CEK-EV-FRM-CS03_CL05-000004.xlsx | Z4: 1MC06-CEK-EV-FRM-CS03_CL05-000004 | AA4: S0 | AB4: Internal review | AC4: Final
A5: 1MC06-CEK-EV-FRM-CS03_CL05-000005 | B5: Wendover Dean North Embankment Landscape Planting - MPDT | C5: Wendover Dean North Embankment Landscape Planting | D5: P01.1 | E5: Work in Progress | F5: Alexander Granados-Potts | G5: 45634.71 | H5: Hub_DC_Birmingham_Central | I5: 44995.593 | J5: Hub_DC_Birmingham_Central | K5: 44995.593 | L5: 58 KB | M5: 1MC06 | N5: P01.1 | O5: North Portal Chiltern Tunnels to Brackley | P5: 01 - Docs | Q5: SDK | R5: HS2_DJV_Documents | S5: 290491 | T5: Microsoft Excel | U5: Wendover Dean North Embankment Landscape Planting - MPDT | V5: 1MC06-CEK-EV-FRM-CS03_CL05-000005.xlsx | Z5: 1MC06-CEK-EV-FRM-CS03_CL05-000005 | AA5: S0 | AB5: Internal review | AC5: Final
A6: 1MC06-CEK-EV-FRM-CS03_CL05-000006 | B6: Wendover Dean South Embankment Landscape Planting - MPDT | C6: Wendover Dean South Embankment Landscape Planting | D6: P01.1 | E6: Work in Progress | F6: Alexander Granados-Potts | G6: 45634.71 | H6: Hub_DC_Birmingham_Central | I6: 44995.593 | J6: Hub_DC_Birmingham_Central | K6: 44995.593 | L6: 58 KB | M6: 1MC06 | N6: P01.1 | O6: North Portal Chiltern Tunnels to Brackley | P6: 01 - Docs | Q6: SDK | R6: HS2_DJV_Documents | S6: 290594 | T6: Microsoft Excel | U6: Wendover Dean South Embankment Landscape Planting - MPDT | V6: 1MC06-CEK-EV-FRM-CS03_CL05-000006.xlsx | Z6: 1MC06-CEK-EV-FRM-CS03_CL05-000006 | AA6: S0 | AB6: Internal review | AC6: Final
A7: 1MC06-CEK-EV-FRM-CS03_CL05-000007 | B7: Wendover Dean Viaduct Landscape Planting - MPDT | C7: Wendover Dean Viaduct Landscape Planting | D7: P01.1 | E7: Unassigned | F7: Alexander Granados-Potts | G7: 45634.71 | H7: Hub_DC_Birmingham_Central | I7: 44995.593 | J7: Hub_DC_Birmingham_Central | K7: 44995.593 | L7: 58 KB | M7: 1MC06 | N7: P01.1 | O7: North Portal Chiltern Tunnels to Brackley | P7: 01 - Docs | Q7: SDK | R7: HS2_DJV_Documents | S7: 290707 | T7: Microsoft Excel | U7: Wendover Dean Viaduct Landscape Planting - MPDT | V7: 1MC06-CEK-EV-FRM-CS03_CL05-000007.xlsx | Z7: 1MC06-CEK-EV-FRM-CS03_CL05-000007 | AA7: S0 | AB7: Internal review | AC7: Final
A8: 1MC06-CEK-EV-FRM-CS03_CL06-000002 | B8: Small Dean North Embankment Landscape Planting - MPDT | C8: Small Dean North Embankment Landscape Planting | D8: P01.1 | E8: Unassigned | F8: Alexander Granados-Potts | G8: 45634.71 | H8: Hub_DC_Birmingham_Central | I8: 44995.593 | J8: Hub_DC_Birmingham_Central | K8: 44995.593 | L8: 58 KB | M8: 1MC06 | N8: P01.1 | O8: North Portal Chiltern Tunnels to Brackley | P8: 01 - Docs | Q8: SDK | R8: HS2_DJV_Documents | S8: 284988 | T8: Microsoft Excel | U8: Small Dean North Embankment Landscape Planting - MPDT | V8: 1MC06-CEK-EV-FRM-CS03_CL06-000002.xlsx | Z8: 1MC06-CEK-EV-FRM-CS03_CL06-000002 | AA8: S0 | AB8: Internal review | AC8: Final
A9: 1MC06-CEK-EV-FRM-CS03_CL06-000004 | B9: Wendover Green Tunnel Landscape Planting - MPDT | C9: Wendover Green Tunnel Landscape Planting | D9: P01.1 | E9: Unassigned | F9: Alexander Granados-Potts | G9: 45634.71 | H9: Hub_DC_Birmingham_Central | I9: 44995.593 | J9: Hub_DC_Birmingham_Central | K9: 44995.593 | L9: 58 KB | M9: 1MC06 | N9: P01.1 | O9: North Portal Chiltern Tunnels to Brackley | P9: 01 - Docs | Q9: SDK | R9: HS2_DJV_Documents | S9: 291607 | T9: Microsoft Excel | U9: Wendover Green Tunnel Landscape Planting - MPDT | V9: 1MC06-CEK-EV-FRM-CS03_CL06-000004.xlsx | Z9: 1MC06-CEK-EV-FRM-CS03_CL06-000004 | AA9: S0 | AB9: Internal review | AC9: Checked In
A10: 1MC06-CEK-EV-FRM-CS03_CL17-000001 | B10: Stoke Mandeville South Embankment Landscape Planting - MPDT | C10: Stoke Mandeville South Embankment Landscape Planting | D10: P01.1 | E10: Unassigned | F10: Alexander Granados-Potts | G10: 45634.71 | H10: Hub_DC_Birmingham_Central | I10: 44995.592 | J10: Hub_DC_Birmingham_Central | K10: 44995.592 | L10: 58 KB | M10: 1MC06 | N10: P01.1 | O10: North Portal Chiltern Tunnels to Brackley | P10: 01 - Docs | Q10: SDK | R10: HS2_DJV_Documents | S10: 286219 | T10: Microsoft Excel | U10: Stoke Mandeville South Embankment Landscape Planting - MPDT | V10: 1MC06-CEK-EV-FRM-CS03_CL17-000001.xlsx | Z10: 1MC06-CEK-EV-FRM-CS03_CL17-000001 | AA10: S0 | AB10: Internal review | AC10: Final
A11: 1MC06-CEK-EV-FRM-CS03_CL17-000002 | B11: Wendover North Cutting Landscape Planting - MPDT | C11: Wendover North Cutting Landscape Planting | D11: P01.1 | E11: Unassigned | F11: Alexander Granados-Potts | G11: 45634.71 | H11: Hub_DC_Birmingham_Central | I11: 44995.593 | J11: Hub_DC_Birmingham_Central | K11: 44995.593 | L11: 58 KB | M11: 1MC06 | N11: P01.1 | O11: North Portal Chiltern Tunnels to Brackley | P11: 01 - Docs | Q11: SDK | R11: HS2_DJV_Documents | S11: 291714 | T11: Microsoft Excel | U11: Wendover North Cutting Landscape Planting - MPDT | V11: 1MC06-CEK-EV-FRM-CS03_CL17-000002.xlsx | Z11: 1MC06-CEK-EV-FRM-CS03_CL17-000002 | AA11: S0 | AB11: Internal review | AC11: Final
A12: 1MC06-CEK-EV-FRM-CS04_CL18-000001 | B12: Aylesbury Embankment Planting - MPDT | C12: Aylesbury Embankment Planting | D12: P01.1 | E12: Unassigned | F12: Alexander Granados-Potts | G12: 45634.712 | H12: Hub_DC_Birmingham_Central | I12: 44995.572 | J12: Hub_DC_Birmingham_Central | K12: 44995.572 | L12: 58 KB | M12: 1MC06 | N12: P01.1 | O12: North Portal Chiltern Tunnels to Brackley | P12: 01 - Docs | Q12: SDK | R12: HS2_DJV_Documents | S12: 242473 | T12: Microsoft Excel | U12: Aylesbury Embankment Planting - MPDT | V12: 1MC06-CEK-EV-FRM-CS04_CL18-000001.xlsx | Z12: 1MC06-CEK-EV-FRM-CS04_CL18-000001 | AA12: S0 | AB12: Internal review | AC12: Final
A13: 1MC06-CEK-EV-FRM-CS04_CL18-000002 | B13: Aylesbury North Cutting Planting - MPDT | C13: Aylesbury North Cutting Planting | D13: P01.1 | E13: Unassigned | F13: Alexander Granados-Potts | G13: 45634.712 | H13: Hub_DC_Birmingham_Central | I13: 44995.572 | J13: Hub_DC_Birmingham_Central | K13: 44995.572 | L13: 58 KB | M13: 1MC06 | N13: P01.1 | O13: North Portal Chiltern Tunnels to Brackley | P13: 01 - Docs | Q13: SDK | R13: HS2_DJV_Documents | S13: 276989 | T13: Microsoft Excel | U13: Aylesbury North Cutting Planting - MPDT | V13: 1MC06-CEK-EV-FRM-CS04_CL18-000002.xlsx | Z13: 1MC06-CEK-EV-FRM-CS04_CL18-000002 | AA13: S0 | AB13: Internal review | AC13: Final
... A26: 1MC06-CEK-EV-FRM-CS04_CL20-000006 | B26: Waddesdon South Cutting Planting - MPDT | C26: Waddesdon South Cutting Planting | D26: P01.1 | E26: Work in Progress | F26: Alexander Granados-Potts | G26: 45634.712 | H26: Hub_DC_Birmingham_Central | I26: 44995.571 | J26: Hub_DC_Birmingham_Central | K26: 44995.571 | L26: 58 KB | M26: 1MC06 | N26: P01.1 | O26: North Portal Chiltern Tunnels to Brackley | P26: 01 - Docs | Q26: SDK | R26: HS2_DJV_Documents | S26: 289595 | T26: Microsoft Excel | U26: Waddesdon South Cutting Planting - MPDT | V26: 1MC06-CEK-EV-FRM-CS04_CL20-000006.xlsx | Z26: 1MC06-CEK-EV-FRM-CS04_CL20-000006 | AA26: S0 | AB26: Internal review | AC26: Final
A27: 1MC07-ASC-EV-FRM-CS07_CL12-900001 | B27: Greatworth South Cutting – Planting – Plot 1 – MPDT | C27: Greatworth South Cutting Planting Plot 1 | D27: P01 | E27: Approve (Shared) | F27: Graham Evans | G27: 45323.574 | H27: Conor Egan | I27: 45327.475 | J27: Hub_DC_Birmingham_Central | K27: 45154.584 | L27: 204 KB | M27: 1MC07 | N27: P01 | O27: Brackley to Long Itchington Wood Green Tunnel South Portal | P27: 01 - Docs | Q27: SDK | R27: HS2_DJV_Documents | S27: 299545 | T27: Microsoft Excel | U27: Greatworth South Cutting – Planting – Plot 1 – MPDT | V27: 1MC07-ASC-EV-FRM-CS07_CL12-900001.xlsm | Y27: APPROVED | Z27: 1MC07-ASC-EV-FRM-CS07_CL12-900001 | AA27: S3 | AB27: Internal Review | AC27: Final
A28: 1MC07-ASC-EV-FRM-CS07_CL12-900002 | B28: Greatworth South Cutting – Planting – Plot 2 – MPDT | C28: Greatworth South Cutting Planting Plot 2 | D28: P01 | E28: Approve (Shared) | F28: Graham Evans | G28: 45323.575 | H28: Conor Egan | I28: 45328.622 | J28: Hub_DC_Birmingham_Central | K28: 45154.584 | L28: 204 KB | M28: 1MC07 | N28: P01 | O28: Brackley to Long Itchington Wood Green Tunnel South Portal | P28: 01 - Docs | Q28: SDK | R28: HS2_DJV_Documents | S28: 299545 | T28: Microsoft Excel | U28: Greatworth South Cutting – Planting – Plot 2 – MPDT | V28: 1MC07-ASC-EV-FRM-CS07_CL12-900002.xlsm | Y28: APPROVED | Z28: 1MC07-ASC-EV-FRM-CS07_CL12-900002 | AA28: S3 | AB28: Internal Review | AC28: Final
A29: 1MC07-ASC-EV-FRM-CS07_CL12-900003 | B29: Greatworth South Cutting – Planting – Plot 3 – MPDT | C29: Greatworth South Cutting Planting Plot 3 | D29: P01 | E29: Approve (Shared) | F29: Graham Evans | G29: 45323.575 | H29: Conor Egan | I29: 45327.476 | J29: Hub_DC_Birmingham_Central | K29: 45154.584 | L29: 207 KB | M29: 1MC07 | N29: P01 | O29: Brackley to Long Itchington Wood Green Tunnel South Portal | P29: 01 - Docs | Q29: SDK | R29: HS2_DJV_Documents | S29: 299545 | T29: Microsoft Excel | U29: Greatworth South Cutting – Planting – Plot 3 – MPDT | V29: 1MC07-ASC-EV-FRM-CS07_CL12-900003.xlsm | Y29: APPROVED | Z29: 1MC07-ASC-EV-FRM-CS07_CL12-900003 | AA29: S3 | AB29: Internal Review | AC29: Final
A30: 1MC07-ASC-EV-FRM-CS07_CL12-900004 | B30: Greatworth South Cutting – Planting – Plot 4 – MPDT | C30: Greatworth South Cutting Planting Plot 4 | D30: P01 | E30: Approve (Shared) | F30: Graham Evans | G30: 45323.576 | H30: Conor Egan | I30: 45327.476 | J30: Hub_DC_Birmingham_Central | K30: 45154.584 | L30: 203 KB | M30: 1MC07 | N30: P01 | O30: Brackley to Long Itchington Wood Green Tunnel South Portal | P30: 01 - Docs | Q30: SDK | R30: HS2_DJV_Documents | S30: 299545 | T30: Microsoft Excel | U30: Greatworth South Cutting – Planting – Plot 4 – MPDT | V30: 1MC07-ASC-EV-FRM-CS07_CL12-900004.xlsm | Y30: APPROVED | Z30: 1MC07-ASC-EV-FRM-CS07_CL12-900004 | AA30: S3 | AB30: Internal Review | AC30: Final
A31: 1MC07-ASC-EV-FRM-CS07_CL12-900005 | B31: Greatworth South Cutting – Planting – Plot 5 – MPDT | C31: Greatworth South Cutting Planting Plot 5 | D31: P01 | E31: Approve (Shared) | F31: Graham Evans | G31: 45323.576 | H31: Conor Egan | I31: 45327.477 | J31: Hub_DC_Birmingham_Central | K31: 45154.584 | L31: 205 KB | M31: 1MC07 | N31: P01 | O31: Brackley to Long Itchington Wood Green Tunnel South Portal | P31: 01 - Docs | Q31: SDK | R31: HS2_DJV_Documents | S31: 299545 | T31: Microsoft Excel | U31: Greatworth South Cutting – Planting – Plot 5 – MPDT | V31: 1MC07-ASC-EV-FRM-CS07_CL12-900005.xlsm | Y31: APPROVED | Z31: 1MC07-ASC-EV-FRM-CS07_CL12-900005 | AA31: S3 | AB31: Internal Review | AC31: Final
A32: 1MC07-ASC-EV-FRM-CS07_CL12-900006 | B32: Greatworth South Cutting – Planting – Plot 6 – MPDT | C32: Greatworth South Cutting Planting Plot 6 | D32: P01 | E32: Approve (Shared) | F32: Graham Evans | G32: 45323.577 | H32: Conor Egan | I32: 45327.48 | J32: Hub_DC_Birmingham_Central | K32: 45154.584 | L32: 204 KB | M32: 1MC07 | N32: P01 | O32: Brackley to Long Itchington Wood Green Tunnel South Portal | P32: 01 - Docs | Q32: SDK | R32: HS2_DJV_Documents | S32: 299545 | T32: Microsoft Excel | U32: Greatworth South Cutting – Planting – Plot 6 – MPDT | V32: 1MC07-ASC-EV-FRM-CS07_CL12-900006.xlsm | Y32: APPROVED | Z32: 1MC07-ASC-EV-FRM-CS07_CL12-900006 | AA32: S3 | AB32: Internal Review | AC32: Final
A33: 1MC07-ASC-EV-FRM-CS07_CL12-900007 | B33: Greatworth South Cutting – Planting – Plot 7 – MPDT | C33: Greatworth South Cutting Planting Plot 7 | D33: P01 | E33: Approve (Shared) | F33: Graham Evans | G33: 45323.58 | H33: Conor Egan | I33: 45327.481 | J33: Hub_DC_Birmingham_Central | K33: 45154.584 | L33: 203 KB | M33: 1MC07 | N33: P01 | O33: Brackley to Long Itchington Wood Green Tunnel South Portal | P33: 01 - Docs | Q33: SDK | R33: HS2_DJV_Documents | S33: 299545 | T33: Microsoft Excel | U33: Greatworth South Cutting – Planting – Plot 7 – MPDT | V33: 1MC07-ASC-EV-FRM-CS07_CL12-900007.xlsm | Y33: APPROVED | Z33: 1MC07-ASC-EV-FRM-CS07_CL12-900007 | AA33: S3 | AB33: Internal Review | AC33: Final
A34: 1MC07-ASC-EV-FRM-CS07_CL12-900008 | B34: Greatworth South Cutting – Planting – Plot 8 – MPDT | C34: Greatworth South Cutting Planting Plot 8 | D34: P01 | E34: Approve (Shared) | F34: Graham Evans | G34: 45323.581 | H34: Graham Evans | I34: 45323.581 | J34: Hub_DC_Birmingham_Central | K34: 45154.584 | L34: 211 KB | M34: 1MC07 | N34: P01 | O34: Brackley to Long Itchington Wood Green Tunnel South Portal | P34: 01 - Docs | Q34: SDK | R34: HS2_DJV_Documents | S34: 299545 | T34: Microsoft Excel | U34: Greatworth South Cutting – Planting – Plot 8 – MPDT | V34: 1MC07-ASC-EV-FRM-CS07_CL12-900008.xlsm | Y34: APPROVED | Z34: 1MC07-ASC-EV-FRM-CS07_CL12-900008 | AA34: S3 | AB34: Internal Review | AC34: Final
A35: 1MC07-ASC-EV-FRM-CS07_CL12-900009 | B35: Greatworth South Cutting – Planting – Plot 9 – MPDT | C35: Greatworth South Cutting Planting Plot 9 | D35: P01 | E35: Approve (Shared) | F35: Graham Evans | G35: 45323.581 | H35: Conor Egan | I35: 45327.482 | J35: Hub_DC_Birmingham_Central | K35: 45154.584 | L35: 203 KB | M35: 1MC07 | N35: P01 | O35: Brackley to Long Itchington Wood Green Tunnel South Portal | P35: 01 - Docs | Q35: SDK | R35: HS2_DJV_Documents | S35: 299545 | T35: Microsoft Excel | U35: Greatworth South Cutting – Planting – Plot 9 – MPDT | V35: 1MC07-ASC-EV-FRM-CS07_CL12-900009.xlsm | Y35: APPROVED | Z35: 1MC07-ASC-EV-FRM-CS07_CL12-900009 | AA35: S3 | AB35: Internal Review | AC35: Final
A36: 1MC07-ASC-EV-FRM-CS07_CL12-900010 | B36: Greatworth South Cutting – Planting – Plot 10 – MPDT | C36: Greatworth South Cutting Planting Plot 10 | D36: P01 | E36: Approve (Shared) | F36: Graham Evans | G36: 45323.582 | H36: Conor Egan | I36: 45327.483 | J36: Hub_DC_Birmingham_Central | K36: 45154.584 | L36: 208 KB | M36: 1MC07 | N36: P01 | O36: Brackley to Long Itchington Wood Green Tunnel South Portal | P36: 01 - Docs | Q36: SDK | R36: HS2_DJV_Documents | S36: 299545 | T36: Microsoft Excel | U36: Greatworth South Cutting – Planting – Plot 10 – MPDT | V36: 1MC07-ASC-EV-FRM-CS07_CL12-900010.xlsm | Y36: APPROVED | Z36: 1MC07-ASC-EV-FRM-CS07_CL12-900010 | AA36: S3 | AB36: Internal Review | AC36: Final
A37: 1MC07-ASC-EV-FRM-CS07_CL12-900011 | B37: Greatworth South Cutting – Planting – Plot 11 – MPDT | C37: Greatworth South Cutting Planting Plot 11 | D37: P01 | E37: Approve (Shared) | F37: Graham Evans | G37: 45323.582 | H37: Conor Egan | I37: 45327.484 | J37: Hub_DC_Birmingham_Central | K37: 45154.584 | L37: 203 KB | M37: 1MC07 | N37: P01 | O37: Brackley to Long Itchington Wood Green Tunnel South Portal | P37: 01 - Docs | Q37: SDK | R37: HS2_DJV_Documents | S37: 299545 | T37: Microsoft Excel | U37: Greatworth South Cutting – Planting – Plot 11 – MPDT | V37: 1MC07-ASC-EV-FRM-CS07_CL12-900011.xlsm | Y37: APPROVED | Z37: 1MC07-ASC-EV-FRM-CS07_CL12-900011 | AA37: S3 | AB37: Internal Review | AC37: Final
A38: 1MC07-ASC-EV-FRM-CS07_CL12-900012 | B38: Greatworth South Cutting – Planting – Plot 12 – MPDT | C38: Greatworth South Cutting Planting Plot 12 | D38: P01 | E38: Approve (Shared) | F38: Graham Evans | G38: 45323.582 | H38: Conor Egan | I38: 45328.376 | J38: Hub_DC_Birmingham_Central | K38: 45154.585 | L38: 207 KB | M38: 1MC07 | N38: P01 | O38: Brackley to Long Itchington Wood Green Tunnel South Portal | P38: 01 - Docs | Q38: SDK | R38: HS2_DJV_Documents | S38: 299545 | T38: Microsoft Excel | U38: Greatworth South Cutting – Planting – Plot 12 – MPDT | V38: 1MC07-ASC-EV-FRM-CS07_CL12-900012.xlsm | Y38: APPROVED | Z38: 1MC07-ASC-EV-FRM-CS07_CL12-900012 | AA38: S3 | AB38: Internal Review | AC38: Final
... A52: 1MC07-CEK-EV-FRM-CS07_CL24-000011 | B52: Withdrawn - Ladbroke Cutting Planting - West Plot 5 - MPDT | C52: Ladbroke Cutting Planting - West Plot 5 | D52: P01.1 | E52: Withdrawn | F52: Alexander Granados-Potts | G52: 45634.797 | H52: Hub_DC_Birmingham_Central | I52: 45146.442 | J52: Hub_DC_Birmingham_Central | K52: 45146.442 | L52: 58 KB | M52: 1MC07 | N52: P01.1 | O52: Brackley to Long Itchington Wood Green Tunnel South Portal | P52: 01 - Docs | Q52: SDK | R52: HS2_DJV_Documents | S52: 301697 | T52: Withdrawn File | U52: Ladbroke Cutting Planting - West Plot 5 - MPDT | V52: 1MC07-CEK-EV-FRM-CS07_CL24-000011.xlsx | Y52: UNAPPROVED | Z52: 1MC07-CEK-EV-FRM-CS07_CL24-000011 | AA52: S0 | AB52: Internal Review | AC52: Final

Sheet MDPTs
A1: Name | B1: Description | D1: Rev.Ver | E1: State | F1: Updated By | G1: Updated | H1: File Updated By | I1: File Updated | J1: Created By | K1: Created | L1: File Size | M1: Project ID | N1: Version | O1: Project Title | P1: Folder Name | Q1: Folder Description | R1: Environment | S1: Folder Id | T1: Application | U1: Title | V1: File Name | W1: Out to | X1: File Revision | Y1: Reference Status | Z1: Doc. Reference | AA1: Suitability | AB1: Revision note | AC1: Status
A2: 1MC06-ASC-EV-FRM-CS06_CL09-900001 | B2: MDPT Calvert Cutting Planting Plot 1 | C2: =TRIM(RIGHT(B2,LEN(B2)-5)) -> Calvert Cutting Planting Plot 1 | D2: P02 | E2: Approve (Shared) | F2: laurence.meyer_inter.setec.fr | G2: 45447.472 | H2: laurence.meyer_inter.setec.fr | I2: 45447.472 | J2: Hub_DC_Birmingham_Central | K2: 45427.378 | L2: 216 KB | M2: 1MC06 | N2: P02 | O2: North Portal Chiltern Tunnels to Brackley | P2: 01 - Docs | Q2: SDK | R2: HS2_DJV_Documents | S2: 278380 | T2: Microsoft Excel | U2: MDPT Calvert Cutting Planting Plot 1 | V2: 1MC06-ASC-EV-FRM-CS06_CL09-900001.xlsm | Y2: APPROVED | Z2: 1MC06-ASC-EV-FRM-CS06_CL09-900001 | AA2: S3 | AB2: Internal Review | AC2: Final
A3: 1MC06-ASC-EV-FRM-CS06_CL09-900001 | B3: MDPT Calvert Cutting Planting Plot 1 | C3: =TRIM(RIGHT(B3,LEN(B3)-5)) -> Calvert Cutting Planting Plot 1 | D3: P01 | E3: Approve (Shared) | F3: Romane Leboucher | G3: 45446.398 | H3: laurence.meyer_inter.setec.fr | I3: 45436.584 | J3: Romane Leboucher | K3: 45427.378 | L3: 229 KB | M3: 1MC06 | N3: P01 | O3: North Portal Chiltern Tunnels to Brackley | P3: 01 - Docs | Q3: SDK | R3: HS2_DJV_Documents | S3: 278380 | T3: Microsoft Excel | U3: MDPT Calvert Cutting Planting Plot 1 | V3: 1MC06-ASC-EV-FRM-CS06_CL09-900001.xlsm | Y3: APPROVED | Z3: 1MC06-ASC-EV-FRM-CS06_CL09-900001 | AA3: S3 | AB3: Internal Review | AC3: Checked In
A4: 1MC06-ASC-EV-FRM-CS06_CL09-900002 | B4: MDPT Calvert Cutting Planting Plot 2 | C4: =TRIM(RIGHT(B4,LEN(B4)-5)) -> Calvert Cutting Planting Plot 2 | D4: P01 | E4: Approve (Shared) | F4: laurence.meyer_inter.setec.fr | G4: 45436.584 | H4: laurence.meyer_inter.setec.fr | I4: 45436.584 | J4: Hub_DC_Birmingham_Central | K4: 45427.378 | L4: 178 KB | M4: 1MC06 | N4: P01 | O4: North Portal Chiltern Tunnels to Brackley | P4: 01 - Docs | Q4: SDK | R4: HS2_DJV_Documents | S4: 278380 | T4: Microsoft Excel | U4: MDPT Calvert Cutting Planting Plot 2 | V4: 1MC06-ASC-EV-FRM-CS06_CL09-900002.xlsm | Y4: APPROVED | Z4: 1MC06-ASC-EV-FRM-CS06_CL09-900002 | AA4: S3 | AB4: Internal Review | AC4: Final
A5: 1MC06-ASC-EV-FRM-CS06_CL09-900003 | B5: MDPT Twyford Embankment planting Plot 1 | C5: =TRIM(RIGHT(B5,LEN(B5)-5)) -> Twyford Embankment planting Plot 1 | D5: P02 | E5: Approve (Shared) | F5: laurence.meyer_inter.setec.fr | G5: 45447.468 | H5: laurence.meyer_inter.setec.fr | I5: 45447.468 | J5: Hub_DC_Birmingham_Central | K5: 45427.378 | L5: 185 KB | M5: 1MC06 | N5: P02 | O5: North Portal Chiltern Tunnels to Brackley | P5: 01 - Docs | Q5: SDK | R5: HS2_DJV_Documents | S5: 288514 | T5: Microsoft Excel | U5: MDPT Twyford Embankment planting Plot 1 | V5: 1MC06-ASC-EV-FRM-CS06_CL09-900003.xlsm | Y5: APPROVED | Z5: 1MC06-ASC-EV-FRM-CS06_CL09-900003 | AA5: S3 | AB5: Internal Review | AC5: Final
A6: 1MC06-ASC-EV-FRM-CS06_CL09-900003 | B6: MDPT Twyford Embankment planting Plot 1 | C6: =TRIM(RIGHT(B6,LEN(B6)-5)) -> Twyford Embankment planting Plot 1 | D6: P01 | E6: Approve (Shared) | F6: Romane Leboucher | G6: 45446.455 | H6: laurence.meyer_inter.setec.fr | I6: 45436.585 | J6: Romane Leboucher | K6: 45427.378 | L6: 184 KB | M6: 1MC06 | N6: P01 | O6: North Portal Chiltern Tunnels to Brackley | P6: 01 - Docs | Q6: SDK | R6: HS2_DJV_Documents | S6: 288514 | T6: Microsoft Excel | U6: MDPT Twyford Embankment planting Plot 1 | V6: 1MC06-ASC-EV-FRM-CS06_CL09-900003.xlsm | Y6: APPROVED | Z6: 1MC06-ASC-EV-FRM-CS06_CL09-900003 | AA6: S3 | AB6: Internal Review | AC6: Checked In
A7: 1MC06-ASC-EV-FRM-CS06_CL09-900004 | B7: MDPT Calvert Cutting Planting Plot 3 | C7: =TRIM(RIGHT(B7,LEN(B7)-5)) -> Calvert Cutting Planting Plot 3 | D7: P01 | E7: Approve (Shared) | F7: laurence.meyer_inter.setec.fr | G7: 45436.584 | H7: laurence.meyer_inter.setec.fr | I7: 45436.584 | J7: Hub_DC_Birmingham_Central | K7: 45427.378 | L7: 178 KB | M7: 1MC06 | N7: P01 | O7: North Portal Chiltern Tunnels to Brackley | P7: 01 - Docs | Q7: SDK | R7: HS2_DJV_Documents | S7: 278380 | T7: Microsoft Excel | U7: MDPT Calvert Cutting Planting Plot 3 | V7: 1MC06-ASC-EV-FRM-CS06_CL09-900004.xlsm | Y7: APPROVED | Z7: 1MC06-ASC-EV-FRM-CS06_CL09-900004 | AA7: S3 | AB7: Internal Review | AC7: Final
A8: 1MC06-ASC-EV-FRM-CS06_CL09-900005 | B8: MDPT Twyford Embankment planting Plot 2 | C8: =TRIM(RIGHT(B8,LEN(B8)-5)) -> Twyford Embankment planting Plot 2 | D8: P01 | E8: Approve (Shared) | F8: laurence.meyer_inter.setec.fr | G8: 45436.585 | H8: laurence.meyer_inter.setec.fr | I8: 45436.585 | J8: Hub_DC_Birmingham_Central | K8: 45427.378 | L8: 181 KB | M8: 1MC06 | N8: P01 | O8: North Portal Chiltern Tunnels to Brackley | P8: 01 - Docs | Q8: SDK | R8: HS2_DJV_Documents | S8: 288514 | T8: Microsoft Excel | U8: MDPT Twyford Embankment planting Plot 2 | V8: 1MC06-ASC-EV-FRM-CS06_CL09-900005.xlsm | Y8: APPROVED | Z8: 1MC06-ASC-EV-FRM-CS06_CL09-900005 | AA8: S3 | AB8: Internal Review | AC8: Final
A9: 1MC06-ASC-EV-FRM-CS06_CL09-900006 | B9: MDPT Calvert Cutting Planting Plot 4 | C9: =TRIM(RIGHT(B9,LEN(B9)-5)) -> Calvert Cutting Planting Plot 4 | D9: P02 | E9: Approve (Shared) | F9: laurence.meyer_inter.setec.fr | G9: 45447.472 | H9: laurence.meyer_inter.setec.fr | I9: 45447.472 | J9: Hub_DC_Birmingham_Central | K9: 45427.378 | L9: 174 KB | M9: 1MC06 | N9: P02 | O9: North Portal Chiltern Tunnels to Brackley | P9: 01 - Docs | Q9: SDK | R9: HS2_DJV_Documents | S9: 278380 | T9: Microsoft Excel | U9: MDPT Calvert Cutting Planting Plot 4 | V9: 1MC06-ASC-EV-FRM-CS06_CL09-900006.xlsm | Y9: APPROVED | Z9: 1MC06-ASC-EV-FRM-CS06_CL09-900006 | AA9: S3 | AB9: Internal Review | AC9: Final
A10: 1MC06-ASC-EV-FRM-CS06_CL09-900006 | B10: MDPT Calvert Cutting Planting Plot 4 | C10: =TRIM(RIGHT(B10,LEN(B10)-5)) -> Calvert Cutting Planting Plot 4 | D10: P01 | E10: Approve (Shared) | F10: Romane Leboucher | G10: 45446.404 | H10: laurence.meyer_inter.setec.fr | I10: 45436.584 | J10: Romane Leboucher | K10: 45427.378 | L10: 187 KB | M10: 1MC06 | N10: P01 | O10: North Portal Chiltern Tunnels to Brackley | P10: 01 - Docs | Q10: SDK | R10: HS2_DJV_Documents | S10: 278380 | T10: Microsoft Excel | U10: MDPT Calvert Cutting Planting Plot 4 | V10: 1MC06-ASC-EV-FRM-CS06_CL09-900006.xlsm | Y10: APPROVED | Z10: 1MC06-ASC-EV-FRM-CS06_CL09-900006 | AA10: S3 | AB10: Internal Review | AC10: Checked In
A11: 1MC06-ASC-EV-FRM-CS06_CL09-900007 | B11: MDPT Twyford Embankment planting Plot 3 | C11: =TRIM(RIGHT(B11,LEN(B11)-5)) -> Twyford Embankment planting Plot 3 | D11: P02 | E11: Approve (Shared) | F11: laurence.meyer_inter.setec.fr | G11: 45447.468 | H11: laurence.meyer_inter.setec.fr | I11: 45447.468 | J11: Hub_DC_Birmingham_Central | K11: 45427.378 | L11: 196 KB | M11: 1MC06 | N11: P02 | O11: North Portal Chiltern Tunnels to Brackley | P11: 01 - Docs | Q11: SDK | R11: HS2_DJV_Documents | S11: 288514 | T11: Microsoft Excel | U11: MDPT Twyford Embankment planting Plot 3 | V11: 1MC06-ASC-EV-FRM-CS06_CL09-900007.xlsm | Y11: APPROVED | Z11: 1MC06-ASC-EV-FRM-CS06_CL09-900007 | AA11: S3 | AB11: Internal Review | AC11: Final
A12: 1MC06-ASC-EV-FRM-CS06_CL09-900007 | B12: MDPT Twyford Embankment planting Plot 3 | C12: =TRIM(RIGHT(B12,LEN(B12)-5)) -> Twyford Embankment planting Plot 3 | D12: P01 | E12: Approve (Shared) | F12: Romane Leboucher | G12: 45446.465 | H12: laurence.meyer_inter.setec.fr | I12: 45436.585 | J12: Romane Leboucher | K12: 45427.378 | L12: 196 KB | M12: 1MC06 | N12: P01 | O12: North Portal Chiltern Tunnels to Brackley | P12: 01 - Docs | Q12: SDK | R12: HS2_DJV_Documents | S12: 288514 | T12: Microsoft Excel | U12: MDPT Twyford Embankment planting Plot 3 | V12: 1MC06-ASC-EV-FRM-CS06_CL09-900007.xlsm | Y12: APPROVED | Z12: 1MC06-ASC-EV-FRM-CS06_CL09-900007 | AA12: S3 | AB12: Internal Review | AC12: Checked In
